 2018-12-11 18:54:11,522 [P3604/D2/T1] INFO  Umbraco.Core.CoreBootManager - Umbraco 7.12.4 application starting on ARIEL-42
 2018-12-11 18:54:11,555 [P3604/D2/T1] INFO  Umbraco.Core.PluginManager - Determining hash of code files on disk
 2018-12-11 18:54:11,582 [P3604/D2/T1] INFO  Umbraco.Core.PluginManager - Hash determined (took 27ms)
 2018-12-11 18:54:11,744 [P3604/D2/T1] INFO  Umbraco.Core.MainDom - Acquiring MainDom...
 2018-12-11 18:54:11,747 [P3604/D2/T1] INFO  Umbraco.Core.MainDom - Acquired MainDom.
 2018-12-11 18:54:11,749 [P3604/D2/T1] INFO  Umbraco.Core.PluginManager - Resolving umbraco.interfaces.IDiscoverable
 2018-12-11 18:54:12,622 [P3604/D2/T1] INFO  Umbraco.Core.PluginManager - Resolved umbraco.interfaces.IDiscoverable (took 872ms)
 2018-12-11 18:54:12,622 [P3604/D2/T1] INFO  Umbraco.Core.PluginManager - Resolving umbraco.interfaces.IApplicationStartupHandler
 2018-12-11 18:54:12,638 [P3604/D2/T1] INFO  Umbraco.Core.PluginManager - Resolved umbraco.interfaces.IApplicationStartupHandler (took 16ms)
 2018-12-11 18:54:12,666 [P3604/D2/T1] INFO  Umbraco.Core.PluginManager - Resolving umbraco.interfaces.IDiscoverable
 2018-12-11 18:54:12,667 [P3604/D2/T1] INFO  Umbraco.Core.PluginManager - Resolved umbraco.interfaces.IDiscoverable (took 0ms)
 2018-12-11 18:54:12,668 [P3604/D2/T1] INFO  Umbraco.Core.PluginManager - Resolving Umbraco.Core.PropertyEditors.IPropertyEditorValueConverter
 2018-12-11 18:54:12,677 [P3604/D2/T1] INFO  Umbraco.Core.PluginManager - Resolved Umbraco.Core.PropertyEditors.IPropertyEditorValueConverter (took 9ms)
 2018-12-11 18:54:12,678 [P3604/D2/T1] INFO  Umbraco.Core.PluginManager - Resolving umbraco.interfaces.IDiscoverable
 2018-12-11 18:54:12,678 [P3604/D2/T1] INFO  Umbraco.Core.PluginManager - Resolved umbraco.interfaces.IDiscoverable (took 0ms)
 2018-12-11 18:54:12,678 [P3604/D2/T1] INFO  Umbraco.Core.PluginManager - Resolving Umbraco.Core.PropertyEditors.IPropertyValueConverter
 2018-12-11 18:54:12,689 [P3604/D2/T1] INFO  Umbraco.Core.PluginManager - Resolved Umbraco.Core.PropertyEditors.IPropertyValueConverter (took 10ms)
 2018-12-11 18:54:12,724 [P3604/D2/T1] INFO  Umbraco.Core.PluginManager - Resolving umbraco.interfaces.IDiscoverable
 2018-12-11 18:54:12,724 [P3604/D2/T1] INFO  Umbraco.Core.PluginManager - Resolved umbraco.interfaces.IDiscoverable (took 0ms)
 2018-12-11 18:54:12,724 [P3604/D2/T1] INFO  Umbraco.Core.PluginManager - Resolving Umbraco.Web.Mvc.SurfaceController
 2018-12-11 18:54:12,737 [P3604/D2/T1] INFO  Umbraco.Core.PluginManager - Resolved Umbraco.Web.Mvc.SurfaceController (took 12ms)
 2018-12-11 18:54:12,738 [P3604/D2/T1] INFO  Umbraco.Core.PluginManager - Resolving umbraco.interfaces.IDiscoverable
 2018-12-11 18:54:12,739 [P3604/D2/T1] INFO  Umbraco.Core.PluginManager - Resolved umbraco.interfaces.IDiscoverable (took 0ms)
 2018-12-11 18:54:12,739 [P3604/D2/T1] INFO  Umbraco.Core.PluginManager - Resolving Umbraco.Web.WebApi.UmbracoApiController
 2018-12-11 18:54:12,750 [P3604/D2/T1] INFO  Umbraco.Core.PluginManager - Resolved Umbraco.Web.WebApi.UmbracoApiController (took 10ms)
 2018-12-11 18:54:30,033 [P3604/D2/T1] WARN  Umbraco.Core.Persistence.DbConnectionExtensions - Configured database is reporting as not being available! DataSource: ARIEL-42\MSSQLSERVER14, InitialCatalog: Roznamah2. Exception: System.Data.SqlClient.SqlException (0x80131904): A network-related or instance-specific error occurred while establishing a connection to SQL Server. The server was not found or was not accessible. Verify that the instance name is correct and that SQL Server is configured to allow remote connections. (provider: TCP Provider, error: 0 - The remote computer refused the network connection.) ---> System.ComponentModel.Win32Exception (0x80004005): The remote computer refused the network connection
   at System.Data.SqlClient.SqlInternalConnectionTds..ctor(DbConnectionPoolIdentity identity, SqlConnectionString connectionOptions, SqlCredential credential, Object providerInfo, String newPassword, SecureString newSecurePassword, Boolean redirectedUserInstance, SqlConnectionString userConnectionOptions, SessionData reconnectSessionData, DbConnectionPool pool, String accessToken, Boolean applyTransientFaultHandling, SqlAuthenticationProviderManager sqlAuthProviderManager)
   at System.Data.SqlClient.SqlConnectionFactory.CreateConnection(DbConnectionOptions options, DbConnectionPoolKey poolKey, Object poolGroupProviderInfo, DbConnectionPool pool, DbConnection owningConnection, DbConnectionOptions userOptions)
   at System.Data.ProviderBase.DbConnectionFactory.CreatePooledConnection(DbConnectionPool pool, DbConnection owningObject, DbConnectionOptions options, DbConnectionPoolKey poolKey, DbConnectionOptions userOptions)
   at System.Data.ProviderBase.DbConnectionPool.CreateObject(DbConnection owningObject, DbConnectionOptions userOptions, DbConnectionInternal oldConnection)
   at System.Data.ProviderBase.DbConnectionPool.UserCreateRequest(DbConnection owningObject, DbConnectionOptions userOptions, DbConnectionInternal oldConnection)
   at System.Data.ProviderBase.DbConnectionPool.TryGetConnection(DbConnection owningObject, UInt32 waitForMultipleObjectsTimeout, Boolean allowCreate, Boolean onlyOneCheckConnection, DbConnectionOptions userOptions, DbConnectionInternal& connection)
   at System.Data.ProviderBase.DbConnectionPool.TryGetConnection(DbConnection owningObject, TaskCompletionSource`1 retry, DbConnectionOptions userOptions, DbConnectionInternal& connection)
   at System.Data.ProviderBase.DbConnectionFactory.TryGetConnection(DbConnection owningConnection, TaskCompletionSource`1 retry, DbConnectionOptions userOptions, DbConnectionInternal oldConnection, DbConnectionInternal& connection)
   at System.Data.ProviderBase.DbConnectionInternal.TryOpenConnectionInternal(DbConnection outerConnection, DbConnectionFactory connectionFactory, TaskCompletionSource`1 retry, DbConnectionOptions userOptions)
   at System.Data.ProviderBase.DbConnectionClosed.TryOpenConnection(DbConnection outerConnection, DbConnectionFactory connectionFactory, TaskCompletionSource`1 retry, DbConnectionOptions userOptions)
   at System.Data.SqlClient.SqlConnection.TryOpenInner(TaskCompletionSource`1 retry)
   at System.Data.SqlClient.SqlConnection.TryOpen(TaskCompletionSource`1 retry)
   at System.Data.SqlClient.SqlConnection.Open()
   at Umbraco.Core.Persistence.DbConnectionExtensions.IsAvailable(IDbConnection connection)
ClientConnectionId:00000000-0000-0000-0000-000000000000
Error Number:1225,State:0,Class:20
 2018-12-11 18:54:30,034 [P3604/D2/T1] INFO  Umbraco.Core.DatabaseContext - CanConnect = False
 2018-12-11 18:54:30,585 [P3604/D2/T1] WARN  Umbraco.Core.Persistence.DbConnectionExtensions - Configured database is reporting as not being available! DataSource: ARIEL-42\MSSQLSERVER14, InitialCatalog: Roznamah2. Exception: System.Data.SqlClient.SqlException (0x80131904): A network-related or instance-specific error occurred while establishing a connection to SQL Server. The server was not found or was not accessible. Verify that the instance name is correct and that SQL Server is configured to allow remote connections. (provider: TCP Provider, error: 0 - The remote computer refused the network connection.) ---> System.ComponentModel.Win32Exception (0x80004005): The remote computer refused the network connection
   at System.Data.ProviderBase.DbConnectionPool.TryGetConnection(DbConnection owningObject, UInt32 waitForMultipleObjectsTimeout, Boolean allowCreate, Boolean onlyOneCheckConnection, DbConnectionOptions userOptions, DbConnectionInternal& connection)
   at System.Data.ProviderBase.DbConnectionPool.TryGetConnection(DbConnection owningObject, TaskCompletionSource`1 retry, DbConnectionOptions userOptions, DbConnectionInternal& connection)
   at System.Data.ProviderBase.DbConnectionFactory.TryGetConnection(DbConnection owningConnection, TaskCompletionSource`1 retry, DbConnectionOptions userOptions, DbConnectionInternal oldConnection, DbConnectionInternal& connection)
   at System.Data.ProviderBase.DbConnectionInternal.TryOpenConnectionInternal(DbConnection outerConnection, DbConnectionFactory connectionFactory, TaskCompletionSource`1 retry, DbConnectionOptions userOptions)
   at System.Data.ProviderBase.DbConnectionClosed.TryOpenConnection(DbConnection outerConnection, DbConnectionFactory connectionFactory, TaskCompletionSource`1 retry, DbConnectionOptions userOptions)
   at System.Data.SqlClient.SqlConnection.TryOpenInner(TaskCompletionSource`1 retry)
   at System.Data.SqlClient.SqlConnection.TryOpen(TaskCompletionSource`1 retry)
   at System.Data.SqlClient.SqlConnection.Open()
   at Umbraco.Core.Persistence.DbConnectionExtensions.IsAvailable(IDbConnection connection)
ClientConnectionId:00000000-0000-0000-0000-000000000000
Error Number:1225,State:0,Class:20
 2018-12-11 18:54:30,585 [P3604/D2/T1] INFO  Umbraco.Core.DatabaseContext - CanConnect = False
 2018-12-11 18:54:31,588 [P3604/D2/T1] WARN  Umbraco.Core.Persistence.DbConnectionExtensions - Configured database is reporting as not being available! DataSource: ARIEL-42\MSSQLSERVER14, InitialCatalog: Roznamah2. Exception: System.Data.SqlClient.SqlException (0x80131904): A network-related or instance-specific error occurred while establishing a connection to SQL Server. The server was not found or was not accessible. Verify that the instance name is correct and that SQL Server is configured to allow remote connections. (provider: TCP Provider, error: 0 - The remote computer refused the network connection.) ---> System.ComponentModel.Win32Exception (0x80004005): The remote computer refused the network connection
   at System.Data.ProviderBase.DbConnectionPool.TryGetConnection(DbConnection owningObject, UInt32 waitForMultipleObjectsTimeout, Boolean allowCreate, Boolean onlyOneCheckConnection, DbConnectionOptions userOptions, DbConnectionInternal& connection)
   at System.Data.ProviderBase.DbConnectionPool.TryGetConnection(DbConnection owningObject, TaskCompletionSource`1 retry, DbConnectionOptions userOptions, DbConnectionInternal& connection)
   at System.Data.ProviderBase.DbConnectionFactory.TryGetConnection(DbConnection owningConnection, TaskCompletionSource`1 retry, DbConnectionOptions userOptions, DbConnectionInternal oldConnection, DbConnectionInternal& connection)
   at System.Data.ProviderBase.DbConnectionInternal.TryOpenConnectionInternal(DbConnection outerConnection, DbConnectionFactory connectionFactory, TaskCompletionSource`1 retry, DbConnectionOptions userOptions)
   at System.Data.ProviderBase.DbConnectionClosed.TryOpenConnection(DbConnection outerConnection, DbConnectionFactory connectionFactory, TaskCompletionSource`1 retry, DbConnectionOptions userOptions)
   at System.Data.SqlClient.SqlConnection.TryOpenInner(TaskCompletionSource`1 retry)
   at System.Data.SqlClient.SqlConnection.TryOpen(TaskCompletionSource`1 retry)
   at System.Data.SqlClient.SqlConnection.Open()
   at Umbraco.Core.Persistence.DbConnectionExtensions.IsAvailable(IDbConnection connection)
ClientConnectionId:00000000-0000-0000-0000-000000000000
Error Number:1225,State:0,Class:20
 2018-12-11 18:54:31,588 [P3604/D2/T1] INFO  Umbraco.Core.DatabaseContext - CanConnect = False
 2018-12-11 18:54:32,592 [P3604/D2/T1] WARN  Umbraco.Core.Persistence.DbConnectionExtensions - Configured database is reporting as not being available! DataSource: ARIEL-42\MSSQLSERVER14, InitialCatalog: Roznamah2. Exception: System.Data.SqlClient.SqlException (0x80131904): A network-related or instance-specific error occurred while establishing a connection to SQL Server. The server was not found or was not accessible. Verify that the instance name is correct and that SQL Server is configured to allow remote connections. (provider: TCP Provider, error: 0 - The remote computer refused the network connection.) ---> System.ComponentModel.Win32Exception (0x80004005): The remote computer refused the network connection
   at System.Data.ProviderBase.DbConnectionPool.TryGetConnection(DbConnection owningObject, UInt32 waitForMultipleObjectsTimeout, Boolean allowCreate, Boolean onlyOneCheckConnection, DbConnectionOptions userOptions, DbConnectionInternal& connection)
   at System.Data.ProviderBase.DbConnectionPool.TryGetConnection(DbConnection owningObject, TaskCompletionSource`1 retry, DbConnectionOptions userOptions, DbConnectionInternal& connection)
   at System.Data.ProviderBase.DbConnectionFactory.TryGetConnection(DbConnection owningConnection, TaskCompletionSource`1 retry, DbConnectionOptions userOptions, DbConnectionInternal oldConnection, DbConnectionInternal& connection)
   at System.Data.ProviderBase.DbConnectionInternal.TryOpenConnectionInternal(DbConnection outerConnection, DbConnectionFactory connectionFactory, TaskCompletionSource`1 retry, DbConnectionOptions userOptions)
   at System.Data.ProviderBase.DbConnectionClosed.TryOpenConnection(DbConnection outerConnection, DbConnectionFactory connectionFactory, TaskCompletionSource`1 retry, DbConnectionOptions userOptions)
   at System.Data.SqlClient.SqlConnection.TryOpenInner(TaskCompletionSource`1 retry)
   at System.Data.SqlClient.SqlConnection.TryOpen(TaskCompletionSource`1 retry)
   at System.Data.SqlClient.SqlConnection.Open()
   at Umbraco.Core.Persistence.DbConnectionExtensions.IsAvailable(IDbConnection connection)
ClientConnectionId:00000000-0000-0000-0000-000000000000
Error Number:1225,State:0,Class:20
 2018-12-11 18:54:32,592 [P3604/D2/T1] INFO  Umbraco.Core.DatabaseContext - CanConnect = False
 2018-12-11 18:54:33,594 [P3604/D2/T1] WARN  Umbraco.Core.Persistence.DbConnectionExtensions - Configured database is reporting as not being available! DataSource: ARIEL-42\MSSQLSERVER14, InitialCatalog: Roznamah2. Exception: System.Data.SqlClient.SqlException (0x80131904): A network-related or instance-specific error occurred while establishing a connection to SQL Server. The server was not found or was not accessible. Verify that the instance name is correct and that SQL Server is configured to allow remote connections. (provider: TCP Provider, error: 0 - The remote computer refused the network connection.) ---> System.ComponentModel.Win32Exception (0x80004005): The remote computer refused the network connection
   at System.Data.ProviderBase.DbConnectionPool.TryGetConnection(DbConnection owningObject, UInt32 waitForMultipleObjectsTimeout, Boolean allowCreate, Boolean onlyOneCheckConnection, DbConnectionOptions userOptions, DbConnectionInternal& connection)
   at System.Data.ProviderBase.DbConnectionPool.TryGetConnection(DbConnection owningObject, TaskCompletionSource`1 retry, DbConnectionOptions userOptions, DbConnectionInternal& connection)
   at System.Data.ProviderBase.DbConnectionFactory.TryGetConnection(DbConnection owningConnection, TaskCompletionSource`1 retry, DbConnectionOptions userOptions, DbConnectionInternal oldConnection, DbConnectionInternal& connection)
   at System.Data.ProviderBase.DbConnectionInternal.TryOpenConnectionInternal(DbConnection outerConnection, DbConnectionFactory connectionFactory, TaskCompletionSource`1 retry, DbConnectionOptions userOptions)
   at System.Data.ProviderBase.DbConnectionClosed.TryOpenConnection(DbConnection outerConnection, DbConnectionFactory connectionFactory, TaskCompletionSource`1 retry, DbConnectionOptions userOptions)
   at System.Data.SqlClient.SqlConnection.TryOpenInner(TaskCompletionSource`1 retry)
   at System.Data.SqlClient.SqlConnection.TryOpen(TaskCompletionSource`1 retry)
   at System.Data.SqlClient.SqlConnection.Open()
   at Umbraco.Core.Persistence.DbConnectionExtensions.IsAvailable(IDbConnection connection)
ClientConnectionId:00000000-0000-0000-0000-000000000000
Error Number:1225,State:0,Class:20
 2018-12-11 18:54:33,594 [P3604/D2/T1] INFO  Umbraco.Core.DatabaseContext - CanConnect = False
 2018-12-11 18:54:34,600 [P3604/D2/T1] WARN  Umbraco.Core.Persistence.DbConnectionExtensions - Configured database is reporting as not being available! DataSource: ARIEL-42\MSSQLSERVER14, InitialCatalog: Roznamah2. Exception: System.Data.SqlClient.SqlException (0x80131904): A network-related or instance-specific error occurred while establishing a connection to SQL Server. The server was not found or was not accessible. Verify that the instance name is correct and that SQL Server is configured to allow remote connections. (provider: TCP Provider, error: 0 - The remote computer refused the network connection.) ---> System.ComponentModel.Win32Exception (0x80004005): The remote computer refused the network connection
   at System.Data.ProviderBase.DbConnectionPool.TryGetConnection(DbConnection owningObject, UInt32 waitForMultipleObjectsTimeout, Boolean allowCreate, Boolean onlyOneCheckConnection, DbConnectionOptions userOptions, DbConnectionInternal& connection)
   at System.Data.ProviderBase.DbConnectionPool.TryGetConnection(DbConnection owningObject, TaskCompletionSource`1 retry, DbConnectionOptions userOptions, DbConnectionInternal& connection)
   at System.Data.ProviderBase.DbConnectionFactory.TryGetConnection(DbConnection owningConnection, TaskCompletionSource`1 retry, DbConnectionOptions userOptions, DbConnectionInternal oldConnection, DbConnectionInternal& connection)
   at System.Data.ProviderBase.DbConnectionInternal.TryOpenConnectionInternal(DbConnection outerConnection, DbConnectionFactory connectionFactory, TaskCompletionSource`1 retry, DbConnectionOptions userOptions)
   at System.Data.ProviderBase.DbConnectionClosed.TryOpenConnection(DbConnection outerConnection, DbConnectionFactory connectionFactory, TaskCompletionSource`1 retry, DbConnectionOptions userOptions)
   at System.Data.SqlClient.SqlConnection.TryOpenInner(TaskCompletionSource`1 retry)
   at System.Data.SqlClient.SqlConnection.TryOpen(TaskCompletionSource`1 retry)
   at System.Data.SqlClient.SqlConnection.Open()
   at Umbraco.Core.Persistence.DbConnectionExtensions.IsAvailable(IDbConnection connection)
ClientConnectionId:00000000-0000-0000-0000-000000000000
Error Number:1225,State:0,Class:20
 2018-12-11 18:54:34,601 [P3604/D2/T1] INFO  Umbraco.Core.DatabaseContext - CanConnect = False
 2018-12-11 18:54:50,150 [P3604/D2/T1] WARN  Umbraco.Core.Persistence.DbConnectionExtensions - Configured database is reporting as not being available! DataSource: ARIEL-42\MSSQLSERVER14, InitialCatalog: Roznamah2. Exception: System.Data.SqlClient.SqlException (0x80131904): A network-related or instance-specific error occurred while establishing a connection to SQL Server. The server was not found or was not accessible. Verify that the instance name is correct and that SQL Server is configured to allow remote connections. (provider: TCP Provider, error: 0 - The remote computer refused the network connection.) ---> System.ComponentModel.Win32Exception (0x80004005): The remote computer refused the network connection
   at System.Data.SqlClient.SqlInternalConnectionTds..ctor(DbConnectionPoolIdentity identity, SqlConnectionString connectionOptions, SqlCredential credential, Object providerInfo, String newPassword, SecureString newSecurePassword, Boolean redirectedUserInstance, SqlConnectionString userConnectionOptions, SessionData reconnectSessionData, DbConnectionPool pool, String accessToken, Boolean applyTransientFaultHandling, SqlAuthenticationProviderManager sqlAuthProviderManager)
   at System.Data.SqlClient.SqlConnectionFactory.CreateConnection(DbConnectionOptions options, DbConnectionPoolKey poolKey, Object poolGroupProviderInfo, DbConnectionPool pool, DbConnection owningConnection, DbConnectionOptions userOptions)
   at System.Data.ProviderBase.DbConnectionFactory.CreatePooledConnection(DbConnectionPool pool, DbConnection owningObject, DbConnectionOptions options, DbConnectionPoolKey poolKey, DbConnectionOptions userOptions)
   at System.Data.ProviderBase.DbConnectionPool.CreateObject(DbConnection owningObject, DbConnectionOptions userOptions, DbConnectionInternal oldConnection)
   at System.Data.ProviderBase.DbConnectionPool.UserCreateRequest(DbConnection owningObject, DbConnectionOptions userOptions, DbConnectionInternal oldConnection)
   at System.Data.ProviderBase.DbConnectionPool.TryGetConnection(DbConnection owningObject, UInt32 waitForMultipleObjectsTimeout, Boolean allowCreate, Boolean onlyOneCheckConnection, DbConnectionOptions userOptions, DbConnectionInternal& connection)
   at System.Data.ProviderBase.DbConnectionPool.TryGetConnection(DbConnection owningObject, TaskCompletionSource`1 retry, DbConnectionOptions userOptions, DbConnectionInternal& connection)
   at System.Data.ProviderBase.DbConnectionFactory.TryGetConnection(DbConnection owningConnection, TaskCompletionSource`1 retry, DbConnectionOptions userOptions, DbConnectionInternal oldConnection, DbConnectionInternal& connection)
   at System.Data.ProviderBase.DbConnectionInternal.TryOpenConnectionInternal(DbConnection outerConnection, DbConnectionFactory connectionFactory, TaskCompletionSource`1 retry, DbConnectionOptions userOptions)
   at System.Data.ProviderBase.DbConnectionClosed.TryOpenConnection(DbConnection outerConnection, DbConnectionFactory connectionFactory, TaskCompletionSource`1 retry, DbConnectionOptions userOptions)
   at System.Data.SqlClient.SqlConnection.TryOpenInner(TaskCompletionSource`1 retry)
   at System.Data.SqlClient.SqlConnection.TryOpen(TaskCompletionSource`1 retry)
   at System.Data.SqlClient.SqlConnection.Open()
   at Umbraco.Core.Persistence.DbConnectionExtensions.IsAvailable(IDbConnection connection)
ClientConnectionId:00000000-0000-0000-0000-000000000000
Error Number:1225,State:0,Class:20
 2018-12-11 18:54:50,151 [P3604/D2/T1] INFO  Umbraco.Core.DatabaseContext - CanConnect = False
 2018-12-11 18:54:50,171 [P3604/D2/T1] ERROR Umbraco.Core.UmbracoApplicationBase - An unhandled exception occurred
Umbraco.Core.Exceptions.UmbracoStartupFailedException: Umbraco cannot start. A connection string is configured but Umbraco cannot connect to the database.
   at Umbraco.Core.CoreBootManager.EnsureDatabaseConnection()
   at Umbraco.Core.CoreBootManager.Complete(Action`1 afterComplete)
   at Umbraco.Web.WebBootManager.Complete(Action`1 afterComplete)
   at Umbraco.Core.UmbracoApplicationBase.StartApplication(Object sender, EventArgs e)
   at Umbraco.Core.UmbracoApplicationBase.Application_Start(Object sender, EventArgs e)
 2018-12-11 18:55:00,225 [P3604/D2/T9] INFO  Umbraco.Core.MainDom - Stopping...
 2018-12-11 18:55:00,225 [P3604/D2/T9] INFO  Umbraco.Web.ExamineStartup - Examine shutting down
 2018-12-11 18:55:00,428 [P3604/D2/T9] INFO  Umbraco.Web.ExamineStartup - Complete (took 194ms)
 2018-12-11 18:55:00,428 [P3604/D2/T9] INFO  Umbraco.Core.MainDom - Released MainDom.
 2018-12-11 18:55:30,507 [P3604/D2/T8] INFO  Umbraco.Core.UmbracoApplicationBase - Application shutdown. Details: InitializationError

_shutDownMessage=Initialization Error
HostingEnvironment initiated shutdown
HostingEnvironment caused shutdown

_shutDownStack=   at System.Environment.GetStackTrace(Exception e, Boolean needFileInfo)
   at System.Environment.get_StackTrace()
   at System.Web.Hosting.HostingEnvironment.InitiateShutdownInternal()
   at System.Web.Hosting.HostingEnvironment.InitiateShutdownWithoutDemand()
   at System.Web.HttpRuntime.ShutdownAppDomain(String stackTrace)
   at System.Web.HttpRuntime.AppDomainShutdownTimerCallback(Object state)
   at System.Threading.TimerQueueTimer.CallCallbackInContext(Object state)
   at System.Threading.ExecutionContext.RunInternal(ExecutionContext executionContext, ContextCallback callback, Object state, Boolean preserveSyncCtx)
   at System.Threading.ExecutionContext.Run(ExecutionContext executionContext, ContextCallback callback, Object state, Boolean preserveSyncCtx)
   at System.Threading.TimerQueueTimer.CallCallback()
   at System.Threading.TimerQueueTimer.Fire()
   at System.Threading.TimerQueue.FireNextTimers()
   at System.Threading.TimerQueue.AppDomainTimerCallback()
 2018-12-11 18:56:31,470 [P396/D2/T1] INFO  Umbraco.Core.CoreBootManager - Umbraco 7.12.4 application starting on ARIEL-42
 2018-12-11 18:56:31,497 [P396/D2/T1] INFO  Umbraco.Core.PluginManager - Determining hash of code files on disk
 2018-12-11 18:56:31,508 [P396/D2/T1] INFO  Umbraco.Core.PluginManager - Hash determined (took 10ms)
 2018-12-11 18:56:31,598 [P396/D2/T1] INFO  Umbraco.Core.MainDom - Acquiring MainDom...
 2018-12-11 18:56:31,600 [P396/D2/T1] INFO  Umbraco.Core.MainDom - Acquired MainDom.
 2018-12-11 18:56:31,603 [P396/D2/T1] INFO  Umbraco.Core.PluginManager - Resolving umbraco.interfaces.IDiscoverable
 2018-12-11 18:56:32,006 [P396/D2/T1] INFO  Umbraco.Core.PluginManager - Resolved umbraco.interfaces.IDiscoverable (took 402ms)
 2018-12-11 18:56:32,006 [P396/D2/T1] INFO  Umbraco.Core.PluginManager - Resolving umbraco.interfaces.IApplicationStartupHandler
 2018-12-11 18:56:32,024 [P396/D2/T1] INFO  Umbraco.Core.PluginManager - Resolved umbraco.interfaces.IApplicationStartupHandler (took 18ms)
 2018-12-11 18:56:32,057 [P396/D2/T1] INFO  Umbraco.Core.PluginManager - Resolving umbraco.interfaces.IDiscoverable
 2018-12-11 18:56:32,058 [P396/D2/T1] INFO  Umbraco.Core.PluginManager - Resolved umbraco.interfaces.IDiscoverable (took 1ms)
 2018-12-11 18:56:32,059 [P396/D2/T1] INFO  Umbraco.Core.PluginManager - Resolving Umbraco.Core.PropertyEditors.IPropertyEditorValueConverter
 2018-12-11 18:56:32,078 [P396/D2/T1] INFO  Umbraco.Core.PluginManager - Resolved Umbraco.Core.PropertyEditors.IPropertyEditorValueConverter (took 19ms)
 2018-12-11 18:56:32,080 [P396/D2/T1] INFO  Umbraco.Core.PluginManager - Resolving umbraco.interfaces.IDiscoverable
 2018-12-11 18:56:32,080 [P396/D2/T1] INFO  Umbraco.Core.PluginManager - Resolved umbraco.interfaces.IDiscoverable (took 0ms)
 2018-12-11 18:56:32,080 [P396/D2/T1] INFO  Umbraco.Core.PluginManager - Resolving Umbraco.Core.PropertyEditors.IPropertyValueConverter
 2018-12-11 18:56:32,099 [P396/D2/T1] INFO  Umbraco.Core.PluginManager - Resolved Umbraco.Core.PropertyEditors.IPropertyValueConverter (took 18ms)
 2018-12-11 18:56:32,129 [P396/D2/T1] INFO  Umbraco.Core.PluginManager - Resolving umbraco.interfaces.IDiscoverable
 2018-12-11 18:56:32,129 [P396/D2/T1] INFO  Umbraco.Core.PluginManager - Resolved umbraco.interfaces.IDiscoverable (took 0ms)
 2018-12-11 18:56:32,130 [P396/D2/T1] INFO  Umbraco.Core.PluginManager - Resolving Umbraco.Web.Mvc.SurfaceController
 2018-12-11 18:56:32,144 [P396/D2/T1] INFO  Umbraco.Core.PluginManager - Resolved Umbraco.Web.Mvc.SurfaceController (took 14ms)
 2018-12-11 18:56:32,145 [P396/D2/T1] INFO  Umbraco.Core.PluginManager - Resolving umbraco.interfaces.IDiscoverable
 2018-12-11 18:56:32,146 [P396/D2/T1] INFO  Umbraco.Core.PluginManager - Resolved umbraco.interfaces.IDiscoverable (took 0ms)
 2018-12-11 18:56:32,146 [P396/D2/T1] INFO  Umbraco.Core.PluginManager - Resolving Umbraco.Web.WebApi.UmbracoApiController
 2018-12-11 18:56:32,159 [P396/D2/T1] INFO  Umbraco.Core.PluginManager - Resolved Umbraco.Web.WebApi.UmbracoApiController (took 13ms)
 2018-12-11 18:56:48,598 [P396/D2/T1] WARN  Umbraco.Core.Persistence.DbConnectionExtensions - Configured database is reporting as not being available! DataSource: ARIEL-42\MSSQLSERVER14, InitialCatalog: Roznamah2. Exception: System.Data.SqlClient.SqlException (0x80131904): A network-related or instance-specific error occurred while establishing a connection to SQL Server. The server was not found or was not accessible. Verify that the instance name is correct and that SQL Server is configured to allow remote connections. (provider: TCP Provider, error: 0 - The remote computer refused the network connection.) ---> System.ComponentModel.Win32Exception (0x80004005): The remote computer refused the network connection
   at System.Data.SqlClient.SqlInternalConnectionTds..ctor(DbConnectionPoolIdentity identity, SqlConnectionString connectionOptions, SqlCredential credential, Object providerInfo, String newPassword, SecureString newSecurePassword, Boolean redirectedUserInstance, SqlConnectionString userConnectionOptions, SessionData reconnectSessionData, DbConnectionPool pool, String accessToken, Boolean applyTransientFaultHandling, SqlAuthenticationProviderManager sqlAuthProviderManager)
   at System.Data.SqlClient.SqlConnectionFactory.CreateConnection(DbConnectionOptions options, DbConnectionPoolKey poolKey, Object poolGroupProviderInfo, DbConnectionPool pool, DbConnection owningConnection, DbConnectionOptions userOptions)
   at System.Data.ProviderBase.DbConnectionFactory.CreatePooledConnection(DbConnectionPool pool, DbConnection owningObject, DbConnectionOptions options, DbConnectionPoolKey poolKey, DbConnectionOptions userOptions)
   at System.Data.ProviderBase.DbConnectionPool.CreateObject(DbConnection owningObject, DbConnectionOptions userOptions, DbConnectionInternal oldConnection)
   at System.Data.ProviderBase.DbConnectionPool.UserCreateRequest(DbConnection owningObject, DbConnectionOptions userOptions, DbConnectionInternal oldConnection)
   at System.Data.ProviderBase.DbConnectionPool.TryGetConnection(DbConnection owningObject, UInt32 waitForMultipleObjectsTimeout, Boolean allowCreate, Boolean onlyOneCheckConnection, DbConnectionOptions userOptions, DbConnectionInternal& connection)
   at System.Data.ProviderBase.DbConnectionPool.TryGetConnection(DbConnection owningObject, TaskCompletionSource`1 retry, DbConnectionOptions userOptions, DbConnectionInternal& connection)
   at System.Data.ProviderBase.DbConnectionFactory.TryGetConnection(DbConnection owningConnection, TaskCompletionSource`1 retry, DbConnectionOptions userOptions, DbConnectionInternal oldConnection, DbConnectionInternal& connection)
   at System.Data.ProviderBase.DbConnectionInternal.TryOpenConnectionInternal(DbConnection outerConnection, DbConnectionFactory connectionFactory, TaskCompletionSource`1 retry, DbConnectionOptions userOptions)
   at System.Data.ProviderBase.DbConnectionClosed.TryOpenConnection(DbConnection outerConnection, DbConnectionFactory connectionFactory, TaskCompletionSource`1 retry, DbConnectionOptions userOptions)
   at System.Data.SqlClient.SqlConnection.TryOpenInner(TaskCompletionSource`1 retry)
   at System.Data.SqlClient.SqlConnection.TryOpen(TaskCompletionSource`1 retry)
   at System.Data.SqlClient.SqlConnection.Open()
   at Umbraco.Core.Persistence.DbConnectionExtensions.IsAvailable(IDbConnection connection)
ClientConnectionId:00000000-0000-0000-0000-000000000000
Error Number:1225,State:0,Class:20
 2018-12-11 18:56:48,599 [P396/D2/T1] INFO  Umbraco.Core.DatabaseContext - CanConnect = False
 2018-12-11 18:56:48,900 [P396/D2/T1] WARN  Umbraco.Core.Persistence.DbConnectionExtensions - Configured database is reporting as not being available! DataSource: ARIEL-42\MSSQLSERVER14, InitialCatalog: Roznamah2. Exception: System.Data.SqlClient.SqlException (0x80131904): A network-related or instance-specific error occurred while establishing a connection to SQL Server. The server was not found or was not accessible. Verify that the instance name is correct and that SQL Server is configured to allow remote connections. (provider: TCP Provider, error: 0 - The remote computer refused the network connection.) ---> System.ComponentModel.Win32Exception (0x80004005): The remote computer refused the network connection
   at System.Data.ProviderBase.DbConnectionPool.TryGetConnection(DbConnection owningObject, UInt32 waitForMultipleObjectsTimeout, Boolean allowCreate, Boolean onlyOneCheckConnection, DbConnectionOptions userOptions, DbConnectionInternal& connection)
   at System.Data.ProviderBase.DbConnectionPool.TryGetConnection(DbConnection owningObject, TaskCompletionSource`1 retry, DbConnectionOptions userOptions, DbConnectionInternal& connection)
   at System.Data.ProviderBase.DbConnectionFactory.TryGetConnection(DbConnection owningConnection, TaskCompletionSource`1 retry, DbConnectionOptions userOptions, DbConnectionInternal oldConnection, DbConnectionInternal& connection)
   at System.Data.ProviderBase.DbConnectionInternal.TryOpenConnectionInternal(DbConnection outerConnection, DbConnectionFactory connectionFactory, TaskCompletionSource`1 retry, DbConnectionOptions userOptions)
   at System.Data.ProviderBase.DbConnectionClosed.TryOpenConnection(DbConnection outerConnection, DbConnectionFactory connectionFactory, TaskCompletionSource`1 retry, DbConnectionOptions userOptions)
   at System.Data.SqlClient.SqlConnection.TryOpenInner(TaskCompletionSource`1 retry)
   at System.Data.SqlClient.SqlConnection.TryOpen(TaskCompletionSource`1 retry)
   at System.Data.SqlClient.SqlConnection.Open()
   at Umbraco.Core.Persistence.DbConnectionExtensions.IsAvailable(IDbConnection connection)
ClientConnectionId:00000000-0000-0000-0000-000000000000
Error Number:1225,State:0,Class:20
 2018-12-11 18:56:48,900 [P396/D2/T1] INFO  Umbraco.Core.DatabaseContext - CanConnect = False
 2018-12-11 18:56:49,903 [P396/D2/T1] WARN  Umbraco.Core.Persistence.DbConnectionExtensions - Configured database is reporting as not being available! DataSource: ARIEL-42\MSSQLSERVER14, InitialCatalog: Roznamah2. Exception: System.Data.SqlClient.SqlException (0x80131904): A network-related or instance-specific error occurred while establishing a connection to SQL Server. The server was not found or was not accessible. Verify that the instance name is correct and that SQL Server is configured to allow remote connections. (provider: TCP Provider, error: 0 - The remote computer refused the network connection.) ---> System.ComponentModel.Win32Exception (0x80004005): The remote computer refused the network connection
   at System.Data.ProviderBase.DbConnectionPool.TryGetConnection(DbConnection owningObject, UInt32 waitForMultipleObjectsTimeout, Boolean allowCreate, Boolean onlyOneCheckConnection, DbConnectionOptions userOptions, DbConnectionInternal& connection)
   at System.Data.ProviderBase.DbConnectionPool.TryGetConnection(DbConnection owningObject, TaskCompletionSource`1 retry, DbConnectionOptions userOptions, DbConnectionInternal& connection)
   at System.Data.ProviderBase.DbConnectionFactory.TryGetConnection(DbConnection owningConnection, TaskCompletionSource`1 retry, DbConnectionOptions userOptions, DbConnectionInternal oldConnection, DbConnectionInternal& connection)
   at System.Data.ProviderBase.DbConnectionInternal.TryOpenConnectionInternal(DbConnection outerConnection, DbConnectionFactory connectionFactory, TaskCompletionSource`1 retry, DbConnectionOptions userOptions)
   at System.Data.ProviderBase.DbConnectionClosed.TryOpenConnection(DbConnection outerConnection, DbConnectionFactory connectionFactory, TaskCompletionSource`1 retry, DbConnectionOptions userOptions)
   at System.Data.SqlClient.SqlConnection.TryOpenInner(TaskCompletionSource`1 retry)
   at System.Data.SqlClient.SqlConnection.TryOpen(TaskCompletionSource`1 retry)
   at System.Data.SqlClient.SqlConnection.Open()
   at Umbraco.Core.Persistence.DbConnectionExtensions.IsAvailable(IDbConnection connection)
ClientConnectionId:00000000-0000-0000-0000-000000000000
Error Number:1225,State:0,Class:20
 2018-12-11 18:56:49,904 [P396/D2/T1] INFO  Umbraco.Core.DatabaseContext - CanConnect = False
 2018-12-11 18:56:50,907 [P396/D2/T1] WARN  Umbraco.Core.Persistence.DbConnectionExtensions - Configured database is reporting as not being available! DataSource: ARIEL-42\MSSQLSERVER14, InitialCatalog: Roznamah2. Exception: System.Data.SqlClient.SqlException (0x80131904): A network-related or instance-specific error occurred while establishing a connection to SQL Server. The server was not found or was not accessible. Verify that the instance name is correct and that SQL Server is configured to allow remote connections. (provider: TCP Provider, error: 0 - The remote computer refused the network connection.) ---> System.ComponentModel.Win32Exception (0x80004005): The remote computer refused the network connection
   at System.Data.ProviderBase.DbConnectionPool.TryGetConnection(DbConnection owningObject, UInt32 waitForMultipleObjectsTimeout, Boolean allowCreate, Boolean onlyOneCheckConnection, DbConnectionOptions userOptions, DbConnectionInternal& connection)
   at System.Data.ProviderBase.DbConnectionPool.TryGetConnection(DbConnection owningObject, TaskCompletionSource`1 retry, DbConnectionOptions userOptions, DbConnectionInternal& connection)
   at System.Data.ProviderBase.DbConnectionFactory.TryGetConnection(DbConnection owningConnection, TaskCompletionSource`1 retry, DbConnectionOptions userOptions, DbConnectionInternal oldConnection, DbConnectionInternal& connection)
   at System.Data.ProviderBase.DbConnectionInternal.TryOpenConnectionInternal(DbConnection outerConnection, DbConnectionFactory connectionFactory, TaskCompletionSource`1 retry, DbConnectionOptions userOptions)
   at System.Data.ProviderBase.DbConnectionClosed.TryOpenConnection(DbConnection outerConnection, DbConnectionFactory connectionFactory, TaskCompletionSource`1 retry, DbConnectionOptions userOptions)
   at System.Data.SqlClient.SqlConnection.TryOpenInner(TaskCompletionSource`1 retry)
   at System.Data.SqlClient.SqlConnection.TryOpen(TaskCompletionSource`1 retry)
   at System.Data.SqlClient.SqlConnection.Open()
   at Umbraco.Core.Persistence.DbConnectionExtensions.IsAvailable(IDbConnection connection)
ClientConnectionId:00000000-0000-0000-0000-000000000000
Error Number:1225,State:0,Class:20
 2018-12-11 18:56:50,908 [P396/D2/T1] INFO  Umbraco.Core.DatabaseContext - CanConnect = False
 2018-12-11 18:56:51,910 [P396/D2/T1] WARN  Umbraco.Core.Persistence.DbConnectionExtensions - Configured database is reporting as not being available! DataSource: ARIEL-42\MSSQLSERVER14, InitialCatalog: Roznamah2. Exception: System.Data.SqlClient.SqlException (0x80131904): A network-related or instance-specific error occurred while establishing a connection to SQL Server. The server was not found or was not accessible. Verify that the instance name is correct and that SQL Server is configured to allow remote connections. (provider: TCP Provider, error: 0 - The remote computer refused the network connection.) ---> System.ComponentModel.Win32Exception (0x80004005): The remote computer refused the network connection
   at System.Data.ProviderBase.DbConnectionPool.TryGetConnection(DbConnection owningObject, UInt32 waitForMultipleObjectsTimeout, Boolean allowCreate, Boolean onlyOneCheckConnection, DbConnectionOptions userOptions, DbConnectionInternal& connection)
   at System.Data.ProviderBase.DbConnectionPool.TryGetConnection(DbConnection owningObject, TaskCompletionSource`1 retry, DbConnectionOptions userOptions, DbConnectionInternal& connection)
   at System.Data.ProviderBase.DbConnectionFactory.TryGetConnection(DbConnection owningConnection, TaskCompletionSource`1 retry, DbConnectionOptions userOptions, DbConnectionInternal oldConnection, DbConnectionInternal& connection)
   at System.Data.ProviderBase.DbConnectionInternal.TryOpenConnectionInternal(DbConnection outerConnection, DbConnectionFactory connectionFactory, TaskCompletionSource`1 retry, DbConnectionOptions userOptions)
   at System.Data.ProviderBase.DbConnectionClosed.TryOpenConnection(DbConnection outerConnection, DbConnectionFactory connectionFactory, TaskCompletionSource`1 retry, DbConnectionOptions userOptions)
   at System.Data.SqlClient.SqlConnection.TryOpenInner(TaskCompletionSource`1 retry)
   at System.Data.SqlClient.SqlConnection.TryOpen(TaskCompletionSource`1 retry)
   at System.Data.SqlClient.SqlConnection.Open()
   at Umbraco.Core.Persistence.DbConnectionExtensions.IsAvailable(IDbConnection connection)
ClientConnectionId:00000000-0000-0000-0000-000000000000
Error Number:1225,State:0,Class:20
 2018-12-11 18:56:51,910 [P396/D2/T1] INFO  Umbraco.Core.DatabaseContext - CanConnect = False
 2018-12-11 18:56:52,913 [P396/D2/T1] WARN  Umbraco.Core.Persistence.DbConnectionExtensions - Configured database is reporting as not being available! DataSource: ARIEL-42\MSSQLSERVER14, InitialCatalog: Roznamah2. Exception: System.Data.SqlClient.SqlException (0x80131904): A network-related or instance-specific error occurred while establishing a connection to SQL Server. The server was not found or was not accessible. Verify that the instance name is correct and that SQL Server is configured to allow remote connections. (provider: TCP Provider, error: 0 - The remote computer refused the network connection.) ---> System.ComponentModel.Win32Exception (0x80004005): The remote computer refused the network connection
   at System.Data.ProviderBase.DbConnectionPool.TryGetConnection(DbConnection owningObject, UInt32 waitForMultipleObjectsTimeout, Boolean allowCreate, Boolean onlyOneCheckConnection, DbConnectionOptions userOptions, DbConnectionInternal& connection)
   at System.Data.ProviderBase.DbConnectionPool.TryGetConnection(DbConnection owningObject, TaskCompletionSource`1 retry, DbConnectionOptions userOptions, DbConnectionInternal& connection)
   at System.Data.ProviderBase.DbConnectionFactory.TryGetConnection(DbConnection owningConnection, TaskCompletionSource`1 retry, DbConnectionOptions userOptions, DbConnectionInternal oldConnection, DbConnectionInternal& connection)
   at System.Data.ProviderBase.DbConnectionInternal.TryOpenConnectionInternal(DbConnection outerConnection, DbConnectionFactory connectionFactory, TaskCompletionSource`1 retry, DbConnectionOptions userOptions)
   at System.Data.ProviderBase.DbConnectionClosed.TryOpenConnection(DbConnection outerConnection, DbConnectionFactory connectionFactory, TaskCompletionSource`1 retry, DbConnectionOptions userOptions)
   at System.Data.SqlClient.SqlConnection.TryOpenInner(TaskCompletionSource`1 retry)
   at System.Data.SqlClient.SqlConnection.TryOpen(TaskCompletionSource`1 retry)
   at System.Data.SqlClient.SqlConnection.Open()
   at Umbraco.Core.Persistence.DbConnectionExtensions.IsAvailable(IDbConnection connection)
ClientConnectionId:00000000-0000-0000-0000-000000000000
Error Number:1225,State:0,Class:20
 2018-12-11 18:56:52,914 [P396/D2/T1] INFO  Umbraco.Core.DatabaseContext - CanConnect = False
 2018-12-11 18:57:08,478 [P396/D2/T1] WARN  Umbraco.Core.Persistence.DbConnectionExtensions - Configured database is reporting as not being available! DataSource: ARIEL-42\MSSQLSERVER14, InitialCatalog: Roznamah2. Exception: System.Data.SqlClient.SqlException (0x80131904): A network-related or instance-specific error occurred while establishing a connection to SQL Server. The server was not found or was not accessible. Verify that the instance name is correct and that SQL Server is configured to allow remote connections. (provider: TCP Provider, error: 0 - The remote computer refused the network connection.) ---> System.ComponentModel.Win32Exception (0x80004005): The remote computer refused the network connection
   at System.Data.SqlClient.SqlInternalConnectionTds..ctor(DbConnectionPoolIdentity identity, SqlConnectionString connectionOptions, SqlCredential credential, Object providerInfo, String newPassword, SecureString newSecurePassword, Boolean redirectedUserInstance, SqlConnectionString userConnectionOptions, SessionData reconnectSessionData, DbConnectionPool pool, String accessToken, Boolean applyTransientFaultHandling, SqlAuthenticationProviderManager sqlAuthProviderManager)
   at System.Data.SqlClient.SqlConnectionFactory.CreateConnection(DbConnectionOptions options, DbConnectionPoolKey poolKey, Object poolGroupProviderInfo, DbConnectionPool pool, DbConnection owningConnection, DbConnectionOptions userOptions)
   at System.Data.ProviderBase.DbConnectionFactory.CreatePooledConnection(DbConnectionPool pool, DbConnection owningObject, DbConnectionOptions options, DbConnectionPoolKey poolKey, DbConnectionOptions userOptions)
   at System.Data.ProviderBase.DbConnectionPool.CreateObject(DbConnection owningObject, DbConnectionOptions userOptions, DbConnectionInternal oldConnection)
   at System.Data.ProviderBase.DbConnectionPool.UserCreateRequest(DbConnection owningObject, DbConnectionOptions userOptions, DbConnectionInternal oldConnection)
   at System.Data.ProviderBase.DbConnectionPool.TryGetConnection(DbConnection owningObject, UInt32 waitForMultipleObjectsTimeout, Boolean allowCreate, Boolean onlyOneCheckConnection, DbConnectionOptions userOptions, DbConnectionInternal& connection)
   at System.Data.ProviderBase.DbConnectionPool.TryGetConnection(DbConnection owningObject, TaskCompletionSource`1 retry, DbConnectionOptions userOptions, DbConnectionInternal& connection)
   at System.Data.ProviderBase.DbConnectionFactory.TryGetConnection(DbConnection owningConnection, TaskCompletionSource`1 retry, DbConnectionOptions userOptions, DbConnectionInternal oldConnection, DbConnectionInternal& connection)
   at System.Data.ProviderBase.DbConnectionInternal.TryOpenConnectionInternal(DbConnection outerConnection, DbConnectionFactory connectionFactory, TaskCompletionSource`1 retry, DbConnectionOptions userOptions)
   at System.Data.ProviderBase.DbConnectionClosed.TryOpenConnection(DbConnection outerConnection, DbConnectionFactory connectionFactory, TaskCompletionSource`1 retry, DbConnectionOptions userOptions)
   at System.Data.SqlClient.SqlConnection.TryOpenInner(TaskCompletionSource`1 retry)
   at System.Data.SqlClient.SqlConnection.TryOpen(TaskCompletionSource`1 retry)
   at System.Data.SqlClient.SqlConnection.Open()
   at Umbraco.Core.Persistence.DbConnectionExtensions.IsAvailable(IDbConnection connection)
ClientConnectionId:00000000-0000-0000-0000-000000000000
Error Number:1225,State:0,Class:20
 2018-12-11 18:57:08,479 [P396/D2/T1] INFO  Umbraco.Core.DatabaseContext - CanConnect = False
 2018-12-11 18:57:08,499 [P396/D2/T1] ERROR Umbraco.Core.UmbracoApplicationBase - An unhandled exception occurred
Umbraco.Core.Exceptions.UmbracoStartupFailedException: Umbraco cannot start. A connection string is configured but Umbraco cannot connect to the database.
   at Umbraco.Core.CoreBootManager.EnsureDatabaseConnection()
   at Umbraco.Core.CoreBootManager.Complete(Action`1 afterComplete)
   at Umbraco.Web.WebBootManager.Complete(Action`1 afterComplete)
   at Umbraco.Core.UmbracoApplicationBase.StartApplication(Object sender, EventArgs e)
   at Umbraco.Core.UmbracoApplicationBase.Application_Start(Object sender, EventArgs e)
 2018-12-11 18:57:18,528 [P396/D2/T7] INFO  Umbraco.Core.MainDom - Stopping...
 2018-12-11 18:57:18,528 [P396/D2/T7] INFO  Umbraco.Web.ExamineStartup - Examine shutting down
 2018-12-11 18:57:18,716 [P396/D2/T7] INFO  Umbraco.Web.ExamineStartup - Complete (took 185ms)
 2018-12-11 18:57:18,716 [P396/D2/T7] INFO  Umbraco.Core.MainDom - Released MainDom.
 2018-12-11 18:57:27,468 [P396/D3/T11] INFO  Umbraco.Core.CoreBootManager - Umbraco 7.12.4 application starting on ARIEL-42
 2018-12-11 18:57:27,495 [P396/D3/T11] INFO  Umbraco.Core.PluginManager - Determining hash of code files on disk
 2018-12-11 18:57:27,505 [P396/D3/T11] INFO  Umbraco.Core.PluginManager - Hash determined (took 10ms)
 2018-12-11 18:57:27,577 [P396/D3/T11] INFO  Umbraco.Core.MainDom - Acquiring MainDom...
 2018-12-11 18:57:27,581 [P396/D3/T11] INFO  Umbraco.Core.MainDom - Acquired MainDom.
 2018-12-11 18:57:27,583 [P396/D3/T11] INFO  Umbraco.Core.PluginManager - Resolving umbraco.interfaces.IDiscoverable
 2018-12-11 18:57:28,144 [P396/D3/T11] INFO  Umbraco.Core.PluginManager - Resolved umbraco.interfaces.IDiscoverable (took 560ms)
 2018-12-11 18:57:28,144 [P396/D3/T11] INFO  Umbraco.Core.PluginManager - Resolving umbraco.interfaces.IApplicationStartupHandler
 2018-12-11 18:57:28,147 [P396/D3/T11] INFO  Umbraco.Core.PluginManager - Resolved umbraco.interfaces.IApplicationStartupHandler (took 2ms)
 2018-12-11 18:57:28,230 [P396/D3/T11] INFO  Umbraco.Core.PluginManager - Resolving umbraco.interfaces.IDiscoverable
 2018-12-11 18:57:28,231 [P396/D3/T11] INFO  Umbraco.Core.PluginManager - Resolved umbraco.interfaces.IDiscoverable (took 1ms)
 2018-12-11 18:57:28,232 [P396/D3/T11] INFO  Umbraco.Core.PluginManager - Resolving Umbraco.Core.PropertyEditors.IPropertyEditorValueConverter
 2018-12-11 18:57:28,232 [P396/D3/T11] INFO  Umbraco.Core.PluginManager - Resolved Umbraco.Core.PropertyEditors.IPropertyEditorValueConverter (took 0ms)
 2018-12-11 18:57:28,233 [P396/D3/T11] INFO  Umbraco.Core.PluginManager - Resolving umbraco.interfaces.IDiscoverable
 2018-12-11 18:57:28,234 [P396/D3/T11] INFO  Umbraco.Core.PluginManager - Resolved umbraco.interfaces.IDiscoverable (took 0ms)
 2018-12-11 18:57:28,234 [P396/D3/T11] INFO  Umbraco.Core.PluginManager - Resolving Umbraco.Core.PropertyEditors.IPropertyValueConverter
 2018-12-11 18:57:28,236 [P396/D3/T11] INFO  Umbraco.Core.PluginManager - Resolved Umbraco.Core.PropertyEditors.IPropertyValueConverter (took 2ms)
 2018-12-11 18:57:28,272 [P396/D3/T11] INFO  Umbraco.Core.PluginManager - Resolving umbraco.interfaces.IDiscoverable
 2018-12-11 18:57:28,273 [P396/D3/T11] INFO  Umbraco.Core.PluginManager - Resolved umbraco.interfaces.IDiscoverable (took 0ms)
 2018-12-11 18:57:28,273 [P396/D3/T11] INFO  Umbraco.Core.PluginManager - Resolving Umbraco.Web.Mvc.SurfaceController
 2018-12-11 18:57:28,274 [P396/D3/T11] INFO  Umbraco.Core.PluginManager - Resolved Umbraco.Web.Mvc.SurfaceController (took 0ms)
 2018-12-11 18:57:28,275 [P396/D3/T11] INFO  Umbraco.Core.PluginManager - Resolving umbraco.interfaces.IDiscoverable
 2018-12-11 18:57:28,275 [P396/D3/T11] INFO  Umbraco.Core.PluginManager - Resolved umbraco.interfaces.IDiscoverable (took 0ms)
 2018-12-11 18:57:28,275 [P396/D3/T11] INFO  Umbraco.Core.PluginManager - Resolving Umbraco.Web.WebApi.UmbracoApiController
 2018-12-11 18:57:28,276 [P396/D3/T11] INFO  Umbraco.Core.PluginManager - Resolved Umbraco.Web.WebApi.UmbracoApiController (took 0ms)
 2018-12-11 18:57:44,962 [P396/D3/T11] WARN  Umbraco.Core.Persistence.DbConnectionExtensions - Configured database is reporting as not being available! DataSource: ARIEL-42\MSSQLSERVER14, InitialCatalog: Roznamah2. Exception: System.Data.SqlClient.SqlException (0x80131904): A network-related or instance-specific error occurred while establishing a connection to SQL Server. The server was not found or was not accessible. Verify that the instance name is correct and that SQL Server is configured to allow remote connections. (provider: TCP Provider, error: 0 - The remote computer refused the network connection.) ---> System.ComponentModel.Win32Exception (0x80004005): The remote computer refused the network connection
   at System.Data.SqlClient.SqlInternalConnectionTds..ctor(DbConnectionPoolIdentity identity, SqlConnectionString connectionOptions, SqlCredential credential, Object providerInfo, String newPassword, SecureString newSecurePassword, Boolean redirectedUserInstance, SqlConnectionString userConnectionOptions, SessionData reconnectSessionData, DbConnectionPool pool, String accessToken, Boolean applyTransientFaultHandling, SqlAuthenticationProviderManager sqlAuthProviderManager)
   at System.Data.SqlClient.SqlConnectionFactory.CreateConnection(DbConnectionOptions options, DbConnectionPoolKey poolKey, Object poolGroupProviderInfo, DbConnectionPool pool, DbConnection owningConnection, DbConnectionOptions userOptions)
   at System.Data.ProviderBase.DbConnectionFactory.CreatePooledConnection(DbConnectionPool pool, DbConnection owningObject, DbConnectionOptions options, DbConnectionPoolKey poolKey, DbConnectionOptions userOptions)
   at System.Data.ProviderBase.DbConnectionPool.CreateObject(DbConnection owningObject, DbConnectionOptions userOptions, DbConnectionInternal oldConnection)
   at System.Data.ProviderBase.DbConnectionPool.UserCreateRequest(DbConnection owningObject, DbConnectionOptions userOptions, DbConnectionInternal oldConnection)
   at System.Data.ProviderBase.DbConnectionPool.TryGetConnection(DbConnection owningObject, UInt32 waitForMultipleObjectsTimeout, Boolean allowCreate, Boolean onlyOneCheckConnection, DbConnectionOptions userOptions, DbConnectionInternal& connection)
   at System.Data.ProviderBase.DbConnectionPool.TryGetConnection(DbConnection owningObject, TaskCompletionSource`1 retry, DbConnectionOptions userOptions, DbConnectionInternal& connection)
   at System.Data.ProviderBase.DbConnectionFactory.TryGetConnection(DbConnection owningConnection, TaskCompletionSource`1 retry, DbConnectionOptions userOptions, DbConnectionInternal oldConnection, DbConnectionInternal& connection)
   at System.Data.ProviderBase.DbConnectionInternal.TryOpenConnectionInternal(DbConnection outerConnection, DbConnectionFactory connectionFactory, TaskCompletionSource`1 retry, DbConnectionOptions userOptions)
   at System.Data.ProviderBase.DbConnectionClosed.TryOpenConnection(DbConnection outerConnection, DbConnectionFactory connectionFactory, TaskCompletionSource`1 retry, DbConnectionOptions userOptions)
   at System.Data.SqlClient.SqlConnection.TryOpenInner(TaskCompletionSource`1 retry)
   at System.Data.SqlClient.SqlConnection.TryOpen(TaskCompletionSource`1 retry)
   at System.Data.SqlClient.SqlConnection.Open()
   at Umbraco.Core.Persistence.DbConnectionExtensions.IsAvailable(IDbConnection connection)
ClientConnectionId:00000000-0000-0000-0000-000000000000
Error Number:1225,State:0,Class:20
 2018-12-11 18:57:44,962 [P396/D3/T11] INFO  Umbraco.Core.DatabaseContext - CanConnect = False
 2018-12-11 18:57:45,209 [P396/D3/T11] WARN  Umbraco.Core.Persistence.DbConnectionExtensions - Configured database is reporting as not being available! DataSource: ARIEL-42\MSSQLSERVER14, InitialCatalog: Roznamah2. Exception: System.Data.SqlClient.SqlException (0x80131904): A network-related or instance-specific error occurred while establishing a connection to SQL Server. The server was not found or was not accessible. Verify that the instance name is correct and that SQL Server is configured to allow remote connections. (provider: TCP Provider, error: 0 - The remote computer refused the network connection.) ---> System.ComponentModel.Win32Exception (0x80004005): The remote computer refused the network connection
   at System.Data.ProviderBase.DbConnectionPool.TryGetConnection(DbConnection owningObject, UInt32 waitForMultipleObjectsTimeout, Boolean allowCreate, Boolean onlyOneCheckConnection, DbConnectionOptions userOptions, DbConnectionInternal& connection)
   at System.Data.ProviderBase.DbConnectionPool.TryGetConnection(DbConnection owningObject, TaskCompletionSource`1 retry, DbConnectionOptions userOptions, DbConnectionInternal& connection)
   at System.Data.ProviderBase.DbConnectionFactory.TryGetConnection(DbConnection owningConnection, TaskCompletionSource`1 retry, DbConnectionOptions userOptions, DbConnectionInternal oldConnection, DbConnectionInternal& connection)
   at System.Data.ProviderBase.DbConnectionInternal.TryOpenConnectionInternal(DbConnection outerConnection, DbConnectionFactory connectionFactory, TaskCompletionSource`1 retry, DbConnectionOptions userOptions)
   at System.Data.ProviderBase.DbConnectionClosed.TryOpenConnection(DbConnection outerConnection, DbConnectionFactory connectionFactory, TaskCompletionSource`1 retry, DbConnectionOptions userOptions)
   at System.Data.SqlClient.SqlConnection.TryOpenInner(TaskCompletionSource`1 retry)
   at System.Data.SqlClient.SqlConnection.TryOpen(TaskCompletionSource`1 retry)
   at System.Data.SqlClient.SqlConnection.Open()
   at Umbraco.Core.Persistence.DbConnectionExtensions.IsAvailable(IDbConnection connection)
ClientConnectionId:00000000-0000-0000-0000-000000000000
Error Number:1225,State:0,Class:20
 2018-12-11 18:57:45,209 [P396/D3/T11] INFO  Umbraco.Core.DatabaseContext - CanConnect = False
 2018-12-11 18:57:46,211 [P396/D3/T11] WARN  Umbraco.Core.Persistence.DbConnectionExtensions - Configured database is reporting as not being available! DataSource: ARIEL-42\MSSQLSERVER14, InitialCatalog: Roznamah2. Exception: System.Data.SqlClient.SqlException (0x80131904): A network-related or instance-specific error occurred while establishing a connection to SQL Server. The server was not found or was not accessible. Verify that the instance name is correct and that SQL Server is configured to allow remote connections. (provider: TCP Provider, error: 0 - The remote computer refused the network connection.) ---> System.ComponentModel.Win32Exception (0x80004005): The remote computer refused the network connection
   at System.Data.ProviderBase.DbConnectionPool.TryGetConnection(DbConnection owningObject, UInt32 waitForMultipleObjectsTimeout, Boolean allowCreate, Boolean onlyOneCheckConnection, DbConnectionOptions userOptions, DbConnectionInternal& connection)
   at System.Data.ProviderBase.DbConnectionPool.TryGetConnection(DbConnection owningObject, TaskCompletionSource`1 retry, DbConnectionOptions userOptions, DbConnectionInternal& connection)
   at System.Data.ProviderBase.DbConnectionFactory.TryGetConnection(DbConnection owningConnection, TaskCompletionSource`1 retry, DbConnectionOptions userOptions, DbConnectionInternal oldConnection, DbConnectionInternal& connection)
   at System.Data.ProviderBase.DbConnectionInternal.TryOpenConnectionInternal(DbConnection outerConnection, DbConnectionFactory connectionFactory, TaskCompletionSource`1 retry, DbConnectionOptions userOptions)
   at System.Data.ProviderBase.DbConnectionClosed.TryOpenConnection(DbConnection outerConnection, DbConnectionFactory connectionFactory, TaskCompletionSource`1 retry, DbConnectionOptions userOptions)
   at System.Data.SqlClient.SqlConnection.TryOpenInner(TaskCompletionSource`1 retry)
   at System.Data.SqlClient.SqlConnection.TryOpen(TaskCompletionSource`1 retry)
   at System.Data.SqlClient.SqlConnection.Open()
   at Umbraco.Core.Persistence.DbConnectionExtensions.IsAvailable(IDbConnection connection)
ClientConnectionId:00000000-0000-0000-0000-000000000000
Error Number:1225,State:0,Class:20
 2018-12-11 18:57:46,211 [P396/D3/T11] INFO  Umbraco.Core.DatabaseContext - CanConnect = False
 2018-12-11 18:57:47,216 [P396/D3/T11] WARN  Umbraco.Core.Persistence.DbConnectionExtensions - Configured database is reporting as not being available! DataSource: ARIEL-42\MSSQLSERVER14, InitialCatalog: Roznamah2. Exception: System.Data.SqlClient.SqlException (0x80131904): A network-related or instance-specific error occurred while establishing a connection to SQL Server. The server was not found or was not accessible. Verify that the instance name is correct and that SQL Server is configured to allow remote connections. (provider: TCP Provider, error: 0 - The remote computer refused the network connection.) ---> System.ComponentModel.Win32Exception (0x80004005): The remote computer refused the network connection
   at System.Data.ProviderBase.DbConnectionPool.TryGetConnection(DbConnection owningObject, UInt32 waitForMultipleObjectsTimeout, Boolean allowCreate, Boolean onlyOneCheckConnection, DbConnectionOptions userOptions, DbConnectionInternal& connection)
   at System.Data.ProviderBase.DbConnectionPool.TryGetConnection(DbConnection owningObject, TaskCompletionSource`1 retry, DbConnectionOptions userOptions, DbConnectionInternal& connection)
   at System.Data.ProviderBase.DbConnectionFactory.TryGetConnection(DbConnection owningConnection, TaskCompletionSource`1 retry, DbConnectionOptions userOptions, DbConnectionInternal oldConnection, DbConnectionInternal& connection)
   at System.Data.ProviderBase.DbConnectionInternal.TryOpenConnectionInternal(DbConnection outerConnection, DbConnectionFactory connectionFactory, TaskCompletionSource`1 retry, DbConnectionOptions userOptions)
   at System.Data.ProviderBase.DbConnectionClosed.TryOpenConnection(DbConnection outerConnection, DbConnectionFactory connectionFactory, TaskCompletionSource`1 retry, DbConnectionOptions userOptions)
   at System.Data.SqlClient.SqlConnection.TryOpenInner(TaskCompletionSource`1 retry)
   at System.Data.SqlClient.SqlConnection.TryOpen(TaskCompletionSource`1 retry)
   at System.Data.SqlClient.SqlConnection.Open()
   at Umbraco.Core.Persistence.DbConnectionExtensions.IsAvailable(IDbConnection connection)
ClientConnectionId:00000000-0000-0000-0000-000000000000
Error Number:1225,State:0,Class:20
 2018-12-11 18:57:47,217 [P396/D3/T11] INFO  Umbraco.Core.DatabaseContext - CanConnect = False
 2018-12-11 18:57:48,221 [P396/D3/T11] WARN  Umbraco.Core.Persistence.DbConnectionExtensions - Configured database is reporting as not being available! DataSource: ARIEL-42\MSSQLSERVER14, InitialCatalog: Roznamah2. Exception: System.Data.SqlClient.SqlException (0x80131904): A network-related or instance-specific error occurred while establishing a connection to SQL Server. The server was not found or was not accessible. Verify that the instance name is correct and that SQL Server is configured to allow remote connections. (provider: TCP Provider, error: 0 - The remote computer refused the network connection.) ---> System.ComponentModel.Win32Exception (0x80004005): The remote computer refused the network connection
   at System.Data.ProviderBase.DbConnectionPool.TryGetConnection(DbConnection owningObject, UInt32 waitForMultipleObjectsTimeout, Boolean allowCreate, Boolean onlyOneCheckConnection, DbConnectionOptions userOptions, DbConnectionInternal& connection)
   at System.Data.ProviderBase.DbConnectionPool.TryGetConnection(DbConnection owningObject, TaskCompletionSource`1 retry, DbConnectionOptions userOptions, DbConnectionInternal& connection)
   at System.Data.ProviderBase.DbConnectionFactory.TryGetConnection(DbConnection owningConnection, TaskCompletionSource`1 retry, DbConnectionOptions userOptions, DbConnectionInternal oldConnection, DbConnectionInternal& connection)
   at System.Data.ProviderBase.DbConnectionInternal.TryOpenConnectionInternal(DbConnection outerConnection, DbConnectionFactory connectionFactory, TaskCompletionSource`1 retry, DbConnectionOptions userOptions)
   at System.Data.ProviderBase.DbConnectionClosed.TryOpenConnection(DbConnection outerConnection, DbConnectionFactory connectionFactory, TaskCompletionSource`1 retry, DbConnectionOptions userOptions)
   at System.Data.SqlClient.SqlConnection.TryOpenInner(TaskCompletionSource`1 retry)
   at System.Data.SqlClient.SqlConnection.TryOpen(TaskCompletionSource`1 retry)
   at System.Data.SqlClient.SqlConnection.Open()
   at Umbraco.Core.Persistence.DbConnectionExtensions.IsAvailable(IDbConnection connection)
ClientConnectionId:00000000-0000-0000-0000-000000000000
Error Number:1225,State:0,Class:20
 2018-12-11 18:57:48,222 [P396/D3/T11] INFO  Umbraco.Core.DatabaseContext - CanConnect = False
 2018-12-11 18:57:48,782 [P396/D2/T7] INFO  Umbraco.Core.UmbracoApplicationBase - Application shutdown. Details: InitializationError

_shutDownMessage=Initialization Error
HostingEnvironment initiated shutdown
HostingEnvironment caused shutdown

_shutDownStack=   at System.Environment.GetStackTrace(Exception e, Boolean needFileInfo)
   at System.Environment.get_StackTrace()
   at System.Web.Hosting.HostingEnvironment.InitiateShutdownInternal()
   at System.Web.Hosting.HostingEnvironment.InitiateShutdownWithoutDemand()
   at System.Web.HttpRuntime.ShutdownAppDomain(String stackTrace)
   at System.Web.HttpRuntime.AppDomainShutdownTimerCallback(Object state)
   at System.Threading.TimerQueueTimer.CallCallbackInContext(Object state)
   at System.Threading.ExecutionContext.RunInternal(ExecutionContext executionContext, ContextCallback callback, Object state, Boolean preserveSyncCtx)
   at System.Threading.ExecutionContext.Run(ExecutionContext executionContext, ContextCallback callback, Object state, Boolean preserveSyncCtx)
   at System.Threading.TimerQueueTimer.CallCallback()
   at System.Threading.TimerQueueTimer.Fire()
   at System.Threading.TimerQueue.FireNextTimers()
   at System.Threading.TimerQueue.AppDomainTimerCallback()
 2018-12-11 18:57:49,231 [P396/D3/T11] WARN  Umbraco.Core.Persistence.DbConnectionExtensions - Configured database is reporting as not being available! DataSource: ARIEL-42\MSSQLSERVER14, InitialCatalog: Roznamah2. Exception: System.Data.SqlClient.SqlException (0x80131904): A network-related or instance-specific error occurred while establishing a connection to SQL Server. The server was not found or was not accessible. Verify that the instance name is correct and that SQL Server is configured to allow remote connections. (provider: TCP Provider, error: 0 - The remote computer refused the network connection.) ---> System.ComponentModel.Win32Exception (0x80004005): The remote computer refused the network connection
   at System.Data.ProviderBase.DbConnectionPool.TryGetConnection(DbConnection owningObject, UInt32 waitForMultipleObjectsTimeout, Boolean allowCreate, Boolean onlyOneCheckConnection, DbConnectionOptions userOptions, DbConnectionInternal& connection)
   at System.Data.ProviderBase.DbConnectionPool.TryGetConnection(DbConnection owningObject, TaskCompletionSource`1 retry, DbConnectionOptions userOptions, DbConnectionInternal& connection)
   at System.Data.ProviderBase.DbConnectionFactory.TryGetConnection(DbConnection owningConnection, TaskCompletionSource`1 retry, DbConnectionOptions userOptions, DbConnectionInternal oldConnection, DbConnectionInternal& connection)
   at System.Data.ProviderBase.DbConnectionInternal.TryOpenConnectionInternal(DbConnection outerConnection, DbConnectionFactory connectionFactory, TaskCompletionSource`1 retry, DbConnectionOptions userOptions)
   at System.Data.ProviderBase.DbConnectionClosed.TryOpenConnection(DbConnection outerConnection, DbConnectionFactory connectionFactory, TaskCompletionSource`1 retry, DbConnectionOptions userOptions)
   at System.Data.SqlClient.SqlConnection.TryOpenInner(TaskCompletionSource`1 retry)
   at System.Data.SqlClient.SqlConnection.TryOpen(TaskCompletionSource`1 retry)
   at System.Data.SqlClient.SqlConnection.Open()
   at Umbraco.Core.Persistence.DbConnectionExtensions.IsAvailable(IDbConnection connection)
ClientConnectionId:00000000-0000-0000-0000-000000000000
Error Number:1225,State:0,Class:20
 2018-12-11 18:57:49,231 [P396/D3/T11] INFO  Umbraco.Core.DatabaseContext - CanConnect = False
 2018-12-11 18:58:04,786 [P396/D3/T11] WARN  Umbraco.Core.Persistence.DbConnectionExtensions - Configured database is reporting as not being available! DataSource: ARIEL-42\MSSQLSERVER14, InitialCatalog: Roznamah2. Exception: System.Data.SqlClient.SqlException (0x80131904): A network-related or instance-specific error occurred while establishing a connection to SQL Server. The server was not found or was not accessible. Verify that the instance name is correct and that SQL Server is configured to allow remote connections. (provider: TCP Provider, error: 0 - The remote computer refused the network connection.) ---> System.ComponentModel.Win32Exception (0x80004005): The remote computer refused the network connection
   at System.Data.SqlClient.SqlInternalConnectionTds..ctor(DbConnectionPoolIdentity identity, SqlConnectionString connectionOptions, SqlCredential credential, Object providerInfo, String newPassword, SecureString newSecurePassword, Boolean redirectedUserInstance, SqlConnectionString userConnectionOptions, SessionData reconnectSessionData, DbConnectionPool pool, String accessToken, Boolean applyTransientFaultHandling, SqlAuthenticationProviderManager sqlAuthProviderManager)
   at System.Data.SqlClient.SqlConnectionFactory.CreateConnection(DbConnectionOptions options, DbConnectionPoolKey poolKey, Object poolGroupProviderInfo, DbConnectionPool pool, DbConnection owningConnection, DbConnectionOptions userOptions)
   at System.Data.ProviderBase.DbConnectionFactory.CreatePooledConnection(DbConnectionPool pool, DbConnection owningObject, DbConnectionOptions options, DbConnectionPoolKey poolKey, DbConnectionOptions userOptions)
   at System.Data.ProviderBase.DbConnectionPool.CreateObject(DbConnection owningObject, DbConnectionOptions userOptions, DbConnectionInternal oldConnection)
   at System.Data.ProviderBase.DbConnectionPool.UserCreateRequest(DbConnection owningObject, DbConnectionOptions userOptions, DbConnectionInternal oldConnection)
   at System.Data.ProviderBase.DbConnectionPool.TryGetConnection(DbConnection owningObject, UInt32 waitForMultipleObjectsTimeout, Boolean allowCreate, Boolean onlyOneCheckConnection, DbConnectionOptions userOptions, DbConnectionInternal& connection)
   at System.Data.ProviderBase.DbConnectionPool.TryGetConnection(DbConnection owningObject, TaskCompletionSource`1 retry, DbConnectionOptions userOptions, DbConnectionInternal& connection)
   at System.Data.ProviderBase.DbConnectionFactory.TryGetConnection(DbConnection owningConnection, TaskCompletionSource`1 retry, DbConnectionOptions userOptions, DbConnectionInternal oldConnection, DbConnectionInternal& connection)
   at System.Data.ProviderBase.DbConnectionInternal.TryOpenConnectionInternal(DbConnection outerConnection, DbConnectionFactory connectionFactory, TaskCompletionSource`1 retry, DbConnectionOptions userOptions)
   at System.Data.ProviderBase.DbConnectionClosed.TryOpenConnection(DbConnection outerConnection, DbConnectionFactory connectionFactory, TaskCompletionSource`1 retry, DbConnectionOptions userOptions)
   at System.Data.SqlClient.SqlConnection.TryOpenInner(TaskCompletionSource`1 retry)
   at System.Data.SqlClient.SqlConnection.TryOpen(TaskCompletionSource`1 retry)
   at System.Data.SqlClient.SqlConnection.Open()
   at Umbraco.Core.Persistence.DbConnectionExtensions.IsAvailable(IDbConnection connection)
ClientConnectionId:00000000-0000-0000-0000-000000000000
Error Number:1225,State:0,Class:20
 2018-12-11 18:58:04,787 [P396/D3/T11] INFO  Umbraco.Core.DatabaseContext - CanConnect = False
 2018-12-11 18:58:04,793 [P396/D3/T11] ERROR Umbraco.Core.UmbracoApplicationBase - An unhandled exception occurred
Umbraco.Core.Exceptions.UmbracoStartupFailedException: Umbraco cannot start. A connection string is configured but Umbraco cannot connect to the database.
   at Umbraco.Core.CoreBootManager.EnsureDatabaseConnection()
   at Umbraco.Core.CoreBootManager.Complete(Action`1 afterComplete)
   at Umbraco.Web.WebBootManager.Complete(Action`1 afterComplete)
   at Umbraco.Core.UmbracoApplicationBase.StartApplication(Object sender, EventArgs e)
   at Umbraco.Core.UmbracoApplicationBase.Application_Start(Object sender, EventArgs e)
 2018-12-11 18:58:14,954 [P396/D3/T6] INFO  Umbraco.Core.MainDom - Stopping...
 2018-12-11 18:58:14,954 [P396/D3/T6] INFO  Umbraco.Web.ExamineStartup - Examine shutting down
 2018-12-11 18:58:14,954 [P396/D3/T6] INFO  Umbraco.Web.ExamineStartup - Complete (took 1ms)
 2018-12-11 18:58:14,954 [P396/D3/T6] INFO  Umbraco.Core.MainDom - Released MainDom.
 2018-12-11 18:58:45,048 [P396/D3/T7] INFO  Umbraco.Core.UmbracoApplicationBase - Application shutdown. Details: InitializationError

_shutDownMessage=Initialization Error
HostingEnvironment initiated shutdown
HostingEnvironment caused shutdown

_shutDownStack=   at System.Environment.GetStackTrace(Exception e, Boolean needFileInfo)
   at System.Environment.get_StackTrace()
   at System.Web.Hosting.HostingEnvironment.InitiateShutdownInternal()
   at System.Web.Hosting.HostingEnvironment.InitiateShutdownWithoutDemand()
   at System.Web.HttpRuntime.ShutdownAppDomain(String stackTrace)
   at System.Web.HttpRuntime.AppDomainShutdownTimerCallback(Object state)
   at System.Threading.TimerQueueTimer.CallCallbackInContext(Object state)
   at System.Threading.ExecutionContext.RunInternal(ExecutionContext executionContext, ContextCallback callback, Object state, Boolean preserveSyncCtx)
   at System.Threading.ExecutionContext.Run(ExecutionContext executionContext, ContextCallback callback, Object state, Boolean preserveSyncCtx)
   at System.Threading.TimerQueueTimer.CallCallback()
   at System.Threading.TimerQueueTimer.Fire()
   at System.Threading.TimerQueue.FireNextTimers()
   at System.Threading.TimerQueue.AppDomainTimerCallback()
 2018-12-11 18:59:03,567 [P396/D4/T1] INFO  Umbraco.Core.CoreBootManager - Umbraco 7.12.4 application starting on ARIEL-42
 2018-12-11 18:59:03,588 [P396/D4/T1] INFO  Umbraco.Core.PluginManager - Determining hash of code files on disk
 2018-12-11 18:59:03,605 [P396/D4/T1] INFO  Umbraco.Core.PluginManager - Hash determined (took 16ms)
 2018-12-11 18:59:03,638 [P396/D4/T1] INFO  Umbraco.Core.MainDom - Acquiring MainDom...
 2018-12-11 18:59:03,638 [P396/D4/T1] INFO  Umbraco.Core.MainDom - Acquired MainDom.
 2018-12-11 18:59:03,641 [P396/D4/T1] INFO  Umbraco.Core.PluginManager - Resolving umbraco.interfaces.IDiscoverable
 2018-12-11 18:59:04,162 [P396/D4/T1] INFO  Umbraco.Core.PluginManager - Resolved umbraco.interfaces.IDiscoverable (took 520ms)
 2018-12-11 18:59:04,162 [P396/D4/T1] INFO  Umbraco.Core.PluginManager - Resolving umbraco.interfaces.IApplicationStartupHandler
 2018-12-11 18:59:04,163 [P396/D4/T1] INFO  Umbraco.Core.PluginManager - Resolved umbraco.interfaces.IApplicationStartupHandler (took 0ms)
 2018-12-11 18:59:04,217 [P396/D4/T1] INFO  Umbraco.Core.PluginManager - Resolving umbraco.interfaces.IDiscoverable
 2018-12-11 18:59:04,218 [P396/D4/T1] INFO  Umbraco.Core.PluginManager - Resolved umbraco.interfaces.IDiscoverable (took 0ms)
 2018-12-11 18:59:04,219 [P396/D4/T1] INFO  Umbraco.Core.PluginManager - Resolving Umbraco.Core.PropertyEditors.IPropertyEditorValueConverter
 2018-12-11 18:59:04,219 [P396/D4/T1] INFO  Umbraco.Core.PluginManager - Resolved Umbraco.Core.PropertyEditors.IPropertyEditorValueConverter (took 0ms)
 2018-12-11 18:59:04,220 [P396/D4/T1] INFO  Umbraco.Core.PluginManager - Resolving umbraco.interfaces.IDiscoverable
 2018-12-11 18:59:04,221 [P396/D4/T1] INFO  Umbraco.Core.PluginManager - Resolved umbraco.interfaces.IDiscoverable (took 0ms)
 2018-12-11 18:59:04,221 [P396/D4/T1] INFO  Umbraco.Core.PluginManager - Resolving Umbraco.Core.PropertyEditors.IPropertyValueConverter
 2018-12-11 18:59:04,223 [P396/D4/T1] INFO  Umbraco.Core.PluginManager - Resolved Umbraco.Core.PropertyEditors.IPropertyValueConverter (took 2ms)
 2018-12-11 18:59:04,230 [P396/D4/T1] INFO  Umbraco.Core.PluginManager - Resolving umbraco.interfaces.IDiscoverable
 2018-12-11 18:59:04,231 [P396/D4/T1] INFO  Umbraco.Core.PluginManager - Resolved umbraco.interfaces.IDiscoverable (took 0ms)
 2018-12-11 18:59:04,231 [P396/D4/T1] INFO  Umbraco.Core.PluginManager - Resolving Umbraco.Web.Mvc.SurfaceController
 2018-12-11 18:59:04,232 [P396/D4/T1] INFO  Umbraco.Core.PluginManager - Resolved Umbraco.Web.Mvc.SurfaceController (took 0ms)
 2018-12-11 18:59:04,232 [P396/D4/T1] INFO  Umbraco.Core.PluginManager - Resolving umbraco.interfaces.IDiscoverable
 2018-12-11 18:59:04,232 [P396/D4/T1] INFO  Umbraco.Core.PluginManager - Resolved umbraco.interfaces.IDiscoverable (took 0ms)
 2018-12-11 18:59:04,232 [P396/D4/T1] INFO  Umbraco.Core.PluginManager - Resolving Umbraco.Web.WebApi.UmbracoApiController
 2018-12-11 18:59:04,233 [P396/D4/T1] INFO  Umbraco.Core.PluginManager - Resolved Umbraco.Web.WebApi.UmbracoApiController (took 0ms)
 2018-12-11 18:59:06,151 [P396/D4/T1] INFO  Umbraco.Core.DatabaseContext - CanConnect = True
 2018-12-11 18:59:08,230 [P396/D4/T1] INFO  Umbraco.Web.Cache.CacheRefresherEventHandler - Initializing Umbraco internal event handlers for cache refreshing
 2018-12-11 18:59:09,534 [P396/D4/T1] INFO  Umbraco.Web.Search.ExamineEvents - Initializing Examine and binding to business logic events
 2018-12-11 18:59:09,536 [P396/D4/T1] INFO  Umbraco.Web.Search.ExamineEvents - Adding examine event handlers for index providers: 3
 2018-12-11 18:59:09,917 [P396/D4/T1] INFO  Umbraco.Core.CoreBootManager - Umbraco application startup complete (took 6464ms)
 2018-12-11 18:59:09,928 [P396/D4/T1] INFO  Umbraco.Web.ExamineStartup - Forcing index InternalIndexSet to be unlocked since it was left in a locked state
 2018-12-11 18:59:09,930 [P396/D4/T1] INFO  Umbraco.Web.ExamineStartup - Forcing index ExternalIndexSet to be unlocked since it was left in a locked state
 2018-12-11 18:59:15,768 [P396/D4/T7] INFO  Umbraco.Core.Sync.ApplicationUrlHelper - New ApplicationUrl detected: http://localhost:8129/umbraco
 2018-12-11 18:59:15,770 [P396/D4/T7] INFO  Umbraco.Core.Sync.ApplicationUrlHelper - ApplicationUrl: http://localhost:8129/umbraco (UmbracoModule request)
 2018-12-11 18:59:18,124 [P396/D4/T7] INFO  umbraco.content - Load Xml from file...
 2018-12-11 18:59:18,129 [P396/D4/T7] INFO  umbraco.content - Loaded Xml from file.
 2018-12-11 18:59:23,179 [P396/D4/T7] INFO  Umbraco.Core.PluginManager - Resolving umbraco.interfaces.IDiscoverable
 2018-12-11 18:59:23,180 [P396/D4/T7] INFO  Umbraco.Core.PluginManager - Resolved umbraco.interfaces.IDiscoverable (took 0ms)
 2018-12-11 18:59:23,180 [P396/D4/T7] INFO  Umbraco.Core.PluginManager - Resolving Umbraco.Core.PropertyEditors.IParameterEditor
 2018-12-11 18:59:23,200 [P396/D4/T7] INFO  Umbraco.Core.PluginManager - Resolved Umbraco.Core.PropertyEditors.IParameterEditor (took 19ms)
 2018-12-11 18:59:33,707 [P396/D4/T7] WARN  Umbraco.Web.UmbracoModule - Status code is 404 yet TrySkipIisCustomErrors is false - IIS will take over.
 2018-12-11 18:59:41,172 [P396/D4/T5] INFO  Umbraco.Core.PluginManager - Resolving umbraco.interfaces.IDiscoverable
 2018-12-11 18:59:41,173 [P396/D4/T5] INFO  Umbraco.Core.PluginManager - Resolved umbraco.interfaces.IDiscoverable (took 0ms)
 2018-12-11 18:59:41,173 [P396/D4/T5] INFO  Umbraco.Core.PluginManager - Resolving [Umbraco.Web.Trees.TreeAttribute]Umbraco.Web.Trees.TreeController
 2018-12-11 18:59:41,200 [P396/D4/T5] INFO  Umbraco.Core.PluginManager - Resolved [Umbraco.Web.Trees.TreeAttribute]Umbraco.Web.Trees.TreeController (took 27ms)
 2018-12-11 18:59:41,594 [P396/D4/T9] INFO  Umbraco.Core.PluginManager - Resolving umbraco.interfaces.IDiscoverable
 2018-12-11 18:59:41,594 [P396/D4/T9] INFO  Umbraco.Core.PluginManager - Resolved umbraco.interfaces.IDiscoverable (took 0ms)
 2018-12-11 18:59:41,595 [P396/D4/T9] INFO  Umbraco.Core.PluginManager - Resolving umbraco.interfaces.IAction
 2018-12-11 18:59:41,611 [P396/D4/T9] INFO  Umbraco.Core.PluginManager - Resolved umbraco.interfaces.IAction (took 16ms)
 2018-12-11 18:59:46,432 [P396/D4/T8] INFO  Umbraco.Core.Security.BackOfficeSignInManager - Event Id: 0, state: Login attempt succeeded for username amit.chawla.mca@live.com from IP address ::1
 2018-12-11 18:59:46,435 [P396/D4/T8] INFO  Umbraco.Core.Security.BackOfficeSignInManager - Event Id: 0, state: User: amit.chawla.mca@live.com logged in from IP address ::1
 2018-12-11 18:59:47,620 [P396/D4/T7] INFO  Umbraco.Core.PluginManager - Resolving umbraco.interfaces.IDiscoverable
 2018-12-11 18:59:47,620 [P396/D4/T7] INFO  Umbraco.Core.PluginManager - Resolved umbraco.interfaces.IDiscoverable (took 0ms)
 2018-12-11 18:59:47,620 [P396/D4/T7] INFO  Umbraco.Core.PluginManager - Resolving umbraco.interfaces.ITree
 2018-12-11 18:59:47,635 [P396/D4/T7] INFO  Umbraco.Core.PluginManager - Resolved umbraco.interfaces.ITree (took 10ms)
 2018-12-11 18:59:47,667 [P396/D4/T7] INFO  Umbraco.Core.PluginManager - Resolving umbraco.interfaces.IDiscoverable
 2018-12-11 18:59:47,667 [P396/D4/T7] INFO  Umbraco.Core.PluginManager - Resolved umbraco.interfaces.IDiscoverable (took 0ms)
 2018-12-11 18:59:47,667 [P396/D4/T7] INFO  Umbraco.Core.PluginManager - Resolving [Umbraco.Web.Trees.TreeAttribute]Umbraco.Web.Trees.TreeController
 2018-12-11 18:59:47,667 [P396/D4/T7] INFO  Umbraco.Core.PluginManager - Resolved [Umbraco.Web.Trees.TreeAttribute]Umbraco.Web.Trees.TreeController (took 0ms)
 2018-12-11 18:59:47,667 [P396/D4/T7] INFO  Umbraco.Core.PluginManager - Resolving umbraco.interfaces.IDiscoverable
 2018-12-11 18:59:47,667 [P396/D4/T7] INFO  Umbraco.Core.PluginManager - Resolved umbraco.interfaces.IDiscoverable (took 0ms)
 2018-12-11 18:59:47,667 [P396/D4/T7] INFO  Umbraco.Core.PluginManager - Resolving [umbraco.businesslogic.TreeAttribute]umbraco.interfaces.ITree
 2018-12-11 18:59:47,682 [P396/D4/T7] INFO  Umbraco.Core.PluginManager - Resolved [umbraco.businesslogic.TreeAttribute]umbraco.interfaces.ITree (took 14ms)
 2018-12-11 18:59:47,713 [P396/D4/T7] INFO  Umbraco.Core.PluginManager - Resolving umbraco.interfaces.IDiscoverable
 2018-12-11 18:59:47,713 [P396/D4/T7] INFO  Umbraco.Core.PluginManager - Resolved umbraco.interfaces.IDiscoverable (took 0ms)
 2018-12-11 18:59:47,713 [P396/D4/T7] INFO  Umbraco.Core.PluginManager - Resolving [umbraco.businesslogic.ApplicationAttribute]umbraco.interfaces.IApplication
 2018-12-11 18:59:47,729 [P396/D4/T7] INFO  Umbraco.Core.PluginManager - Resolved [umbraco.businesslogic.ApplicationAttribute]umbraco.interfaces.IApplication (took 11ms)
 2018-12-11 18:59:49,172 [P396/D4/T13] WARN  Umbraco.Web.Models.Mapping.PreValueDisplayResolver - Could not find persisted pre-value for field maxChars
 2018-12-11 18:59:49,172 [P396/D4/T15] WARN  Umbraco.Web.Models.Mapping.PreValueDisplayResolver - Could not find persisted pre-value for field maxChars
 2018-12-11 18:59:49,264 [P396/D4/T13] WARN  Umbraco.Web.Models.Mapping.PreValueDisplayResolver - Could not find persisted pre-value for field default
 2018-12-11 18:59:49,317 [P396/D4/T15] WARN  Umbraco.Web.Models.Mapping.PreValueDisplayResolver - Could not find persisted pre-value for field maxChars
 2018-12-11 18:59:49,328 [P396/D4/T13] WARN  Umbraco.Web.Models.Mapping.PreValueDisplayResolver - Could not find persisted pre-value for field maxChars
 2018-12-11 18:59:49,348 [P396/D4/T15] WARN  Umbraco.Web.Models.Mapping.PreValueDisplayResolver - Could not find persisted pre-value for field maxChars
 2018-12-11 18:59:49,377 [P396/D4/T13] WARN  Umbraco.Web.Models.Mapping.PreValueDisplayResolver - Could not find persisted pre-value for field maxChars
 2018-12-11 18:59:50,773 [P396/D4/T7] INFO  Umbraco.Core.PluginManager - Resolving umbraco.interfaces.IDiscoverable
 2018-12-11 18:59:50,773 [P396/D4/T7] INFO  Umbraco.Core.PluginManager - Resolved umbraco.interfaces.IDiscoverable (took 0ms)
 2018-12-11 18:59:50,774 [P396/D4/T7] INFO  Umbraco.Core.PluginManager - Resolving [Umbraco.Core.Persistence.Mappers.MapperForAttribute]Umbraco.Core.Persistence.Mappers.BaseMapper
 2018-12-11 18:59:50,852 [P396/D4/T7] INFO  Umbraco.Core.PluginManager - Resolved [Umbraco.Core.Persistence.Mappers.MapperForAttribute]Umbraco.Core.Persistence.Mappers.BaseMapper (took 77ms)
 2018-12-11 18:59:59,096 [P396/D4/T8] INFO  Umbraco.Core.PluginManager - Resolving umbraco.interfaces.IDiscoverable
 2018-12-11 18:59:59,097 [P396/D4/T8] INFO  Umbraco.Core.PluginManager - Resolved umbraco.interfaces.IDiscoverable (took 0ms)
 2018-12-11 18:59:59,097 [P396/D4/T8] INFO  Umbraco.Core.PluginManager - Resolving Umbraco.Core.Deploy.IServiceConnector
 2018-12-11 18:59:59,109 [P396/D4/T8] INFO  Umbraco.Core.PluginManager - Resolved Umbraco.Core.Deploy.IServiceConnector (took 12ms)
 2018-12-11 19:00:18,239 [P396/D4/T9] INFO  Umbraco.Core.PluginManager - Resolving umbraco.interfaces.IDiscoverable
 2018-12-11 19:00:18,240 [P396/D4/T9] INFO  Umbraco.Core.PluginManager - Resolved umbraco.interfaces.IDiscoverable (took 0ms)
 2018-12-11 19:00:18,240 [P396/D4/T9] INFO  Umbraco.Core.PluginManager - Resolving umbraco.interfaces.ICacheRefresher
 2018-12-11 19:00:18,260 [P396/D4/T9] INFO  Umbraco.Core.PluginManager - Resolved umbraco.interfaces.ICacheRefresher (took 19ms)
 2018-12-11 19:00:18,361 [P396/D4/T7] INFO  umbraco.BusinessLogic.Log - Log scrubbed.  Removed all items older than 2018-12-10 19:00:18
 2018-12-11 19:00:22,827 [P396/D4/T7] INFO  umbraco.content - Save Xml to file...
 2018-12-11 19:00:22,855 [P396/D4/T7] INFO  umbraco.content - Saved Xml to file.
 2018-12-11 19:19:19,123 [P396/D4/T103] INFO  Umbraco.Core.Logging.OwinLogger - Event Id: 0, state: User logged will be logged out due to timeout: amit.chawla.mca@live.com, IP Address: ::1
 2018-12-11 19:24:36,528 [P792/D2/T1] INFO  Umbraco.Core.CoreBootManager - Umbraco 7.12.4 application starting on ARIEL-42
 2018-12-11 19:24:36,574 [P792/D2/T1] INFO  Umbraco.Core.PluginManager - Determining hash of code files on disk
 2018-12-11 19:24:36,586 [P792/D2/T1] INFO  Umbraco.Core.PluginManager - Hash determined (took 12ms)
 2018-12-11 19:24:36,684 [P792/D2/T1] INFO  Umbraco.Core.MainDom - Acquiring MainDom...
 2018-12-11 19:24:36,686 [P792/D2/T1] INFO  Umbraco.Core.MainDom - Acquired MainDom.
 2018-12-11 19:24:36,688 [P792/D2/T1] INFO  Umbraco.Core.PluginManager - Resolving umbraco.interfaces.IDiscoverable
 2018-12-11 19:24:37,091 [P792/D2/T1] INFO  Umbraco.Core.PluginManager - Resolved umbraco.interfaces.IDiscoverable (took 402ms)
 2018-12-11 19:24:37,091 [P792/D2/T1] INFO  Umbraco.Core.PluginManager - Resolving umbraco.interfaces.IApplicationStartupHandler
 2018-12-11 19:24:37,101 [P792/D2/T1] INFO  Umbraco.Core.PluginManager - Resolved umbraco.interfaces.IApplicationStartupHandler (took 9ms)
 2018-12-11 19:24:37,130 [P792/D2/T1] INFO  Umbraco.Core.PluginManager - Resolving umbraco.interfaces.IDiscoverable
 2018-12-11 19:24:37,130 [P792/D2/T1] INFO  Umbraco.Core.PluginManager - Resolved umbraco.interfaces.IDiscoverable (took 0ms)
 2018-12-11 19:24:37,131 [P792/D2/T1] INFO  Umbraco.Core.PluginManager - Resolving Umbraco.Core.PropertyEditors.IPropertyEditorValueConverter
 2018-12-11 19:24:37,142 [P792/D2/T1] INFO  Umbraco.Core.PluginManager - Resolved Umbraco.Core.PropertyEditors.IPropertyEditorValueConverter (took 11ms)
 2018-12-11 19:24:37,143 [P792/D2/T1] INFO  Umbraco.Core.PluginManager - Resolving umbraco.interfaces.IDiscoverable
 2018-12-11 19:24:37,144 [P792/D2/T1] INFO  Umbraco.Core.PluginManager - Resolved umbraco.interfaces.IDiscoverable (took 0ms)
 2018-12-11 19:24:37,144 [P792/D2/T1] INFO  Umbraco.Core.PluginManager - Resolving Umbraco.Core.PropertyEditors.IPropertyValueConverter
 2018-12-11 19:24:37,168 [P792/D2/T1] INFO  Umbraco.Core.PluginManager - Resolved Umbraco.Core.PropertyEditors.IPropertyValueConverter (took 24ms)
 2018-12-11 19:24:37,198 [P792/D2/T1] INFO  Umbraco.Core.PluginManager - Resolving umbraco.interfaces.IDiscoverable
 2018-12-11 19:24:37,199 [P792/D2/T1] INFO  Umbraco.Core.PluginManager - Resolved umbraco.interfaces.IDiscoverable (took 0ms)
 2018-12-11 19:24:37,199 [P792/D2/T1] INFO  Umbraco.Core.PluginManager - Resolving Umbraco.Web.Mvc.SurfaceController
 2018-12-11 19:24:37,209 [P792/D2/T1] INFO  Umbraco.Core.PluginManager - Resolved Umbraco.Web.Mvc.SurfaceController (took 10ms)
 2018-12-11 19:24:37,211 [P792/D2/T1] INFO  Umbraco.Core.PluginManager - Resolving umbraco.interfaces.IDiscoverable
 2018-12-11 19:24:37,211 [P792/D2/T1] INFO  Umbraco.Core.PluginManager - Resolved umbraco.interfaces.IDiscoverable (took 0ms)
 2018-12-11 19:24:37,211 [P792/D2/T1] INFO  Umbraco.Core.PluginManager - Resolving Umbraco.Web.WebApi.UmbracoApiController
 2018-12-11 19:24:37,222 [P792/D2/T1] INFO  Umbraco.Core.PluginManager - Resolved Umbraco.Web.WebApi.UmbracoApiController (took 11ms)
 2018-12-11 19:24:39,006 [P792/D2/T1] INFO  Umbraco.Core.DatabaseContext - CanConnect = True
 2018-12-11 19:24:39,243 [P792/D2/T1] INFO  Umbraco.Web.Cache.CacheRefresherEventHandler - Initializing Umbraco internal event handlers for cache refreshing
 2018-12-11 19:24:39,457 [P792/D2/T1] INFO  Umbraco.Web.Search.ExamineEvents - Initializing Examine and binding to business logic events
 2018-12-11 19:24:39,460 [P792/D2/T1] INFO  Umbraco.Web.Search.ExamineEvents - Adding examine event handlers for index providers: 3
 2018-12-11 19:24:39,469 [P792/D2/T1] INFO  Umbraco.Core.CoreBootManager - Umbraco application startup complete (took 3052ms)
 2018-12-11 19:24:39,481 [P792/D2/T1] INFO  Umbraco.Web.ExamineStartup - Forcing index InternalIndexSet to be unlocked since it was left in a locked state
 2018-12-11 19:24:39,483 [P792/D2/T1] INFO  Umbraco.Web.ExamineStartup - Forcing index ExternalIndexSet to be unlocked since it was left in a locked state
 2018-12-11 19:24:39,694 [P792/D2/T11] INFO  Umbraco.Core.Sync.ApplicationUrlHelper - New ApplicationUrl detected: http://localhost:8129/umbraco
 2018-12-11 19:24:39,696 [P792/D2/T11] INFO  Umbraco.Core.Sync.ApplicationUrlHelper - ApplicationUrl: http://localhost:8129/umbraco (UmbracoModule request)
 2018-12-11 19:24:40,064 [P792/D2/T11] INFO  umbraco.content - Load Xml from file...
 2018-12-11 19:24:40,068 [P792/D2/T11] INFO  umbraco.content - Loaded Xml from file.
 2018-12-11 19:24:40,939 [P792/D2/T11] INFO  Umbraco.Core.PluginManager - Resolving umbraco.interfaces.IDiscoverable
 2018-12-11 19:24:40,939 [P792/D2/T11] INFO  Umbraco.Core.PluginManager - Resolved umbraco.interfaces.IDiscoverable (took 0ms)
 2018-12-11 19:24:40,940 [P792/D2/T11] INFO  Umbraco.Core.PluginManager - Resolving Umbraco.Core.PropertyEditors.IParameterEditor
 2018-12-11 19:24:40,951 [P792/D2/T11] INFO  Umbraco.Core.PluginManager - Resolved Umbraco.Core.PropertyEditors.IParameterEditor (took 11ms)
 2018-12-11 19:24:43,253 [P792/D2/T11] WARN  Umbraco.Web.UmbracoModule - Status code is 404 yet TrySkipIisCustomErrors is false - IIS will take over.
 2018-12-11 19:24:45,058 [P792/D2/T12] INFO  Umbraco.Core.PluginManager - Resolving umbraco.interfaces.IDiscoverable
 2018-12-11 19:24:45,058 [P792/D2/T12] INFO  Umbraco.Core.PluginManager - Resolved umbraco.interfaces.IDiscoverable (took 0ms)
 2018-12-11 19:24:45,058 [P792/D2/T12] INFO  Umbraco.Core.PluginManager - Resolving [Umbraco.Web.Trees.TreeAttribute]Umbraco.Web.Trees.TreeController
 2018-12-11 19:24:45,069 [P792/D2/T12] INFO  Umbraco.Core.PluginManager - Resolved [Umbraco.Web.Trees.TreeAttribute]Umbraco.Web.Trees.TreeController (took 10ms)
 2018-12-11 19:24:45,205 [P792/D2/T13] INFO  Umbraco.Core.PluginManager - Resolving umbraco.interfaces.IDiscoverable
 2018-12-11 19:24:45,206 [P792/D2/T13] INFO  Umbraco.Core.PluginManager - Resolved umbraco.interfaces.IDiscoverable (took 0ms)
 2018-12-11 19:24:45,206 [P792/D2/T13] INFO  Umbraco.Core.PluginManager - Resolving umbraco.interfaces.IAction
 2018-12-11 19:24:45,220 [P792/D2/T13] INFO  Umbraco.Core.PluginManager - Resolved umbraco.interfaces.IAction (took 13ms)
